Workbook

Sheet Trường hợp kiểm thử
A1: TEST CASE SYSTEM SPRINT 1
A3: Tên dự án | B3: XÂY DỰNG HỆ THỐNG QUẢN LÝ NHÀ HÀNG THEO MÔ HÌNH TƯƠNG TÁC SỐ ĐA KÊNH
A4: STT | B4: Chức năng | C4: Sheet Name | D4: Số lượng Test | E4: Mô tả
A5: 1 | B5: Đăng nhập (Nhân viên & Khách) | C5: Đăng nhập (Nhân viên & Khách) | D5: ='Đăng nhập (Nhân viên & Khách)'!$F$4 -> 17 | E5: Ngọc
A6: 2 | B6: Đăng ký tài khoản khách hàng | C6: Đăng ký tài khoản khách hàng | D6: ='Đăng ký tài khoản khách hàng'!$F$4 -> 17 | E6: Ngọc
A7: 3 | B7: Quản lý danh mục món ăn | C7: Quản lý danh mục món ăn | D7: ='Quản lý danh mục món ăn'!$F$4 -> 22 | E7: Hiếu
A8: 4 | B8: Quản lý món ăn | C8: Quản lý món ăn | D8: ='Quản lý món ăn'!$F$4 -> 23 | E8: Hiếu
A9: 5 | B9: Quản lý bàn | C9: Quản lý bàn | D9: ='Quản lý bàn'!$F$4 -> 39 | E9: Lâm
A10: 6 | B10: Quét mã QR để truy cập menu | C10: Quét mã QR để truy cập menu | D10: ='Quét mã QR để truy cập menu'!$F$4 -> 22 | E10: Nam
A11: 7 | B11: Xem menu tại bàn | C11: Xem menu tại bàn | D11: ='Xem menu tại bàn'!$F$4 -> 18 | E11: Lâm
A12: 8 | B12: Gọi món tại bàn | C12: Gọi món tại bàn | D12: ='Gọi món tại bàn'!$F$4 -> 18 | E12: Nam
A13: 9 | B13: Xem danh sách món đã gọi | C13: Xem danh sách món đã gọi | D13: ='Xem danh sách món đã gọi'!$F$4 -> 18 | E13: Lâm
A14: 10 | B14: Khởi tạo đơn hàng cho bàn | C14: Khởi tạo đơn hàng cho bàn | D14: ='Khởi tạo đơn hàng cho bàn'!$F$4 -> 16 | E14: Lâm
A15: 11 | B15: Chuyển đơn hàng tới bếp | C15: Chuyển đơn hàng tới bếp | D15: ='Chuyển đơn hàng tới bếp'!$F$4 -> 4 | E15: Khiêm
A16: 12 | B16: Xem danh sách món cần nấu | C16: Xem danh sách món cần nấu | D16: ='Xem danh sách món cần nấu'!$F$4 -> 6 | E16: Khiêm
A17: 13 | B17: Cập nhật trạng thái món ăn | C17: Cập nhật trạng thái món ăn | D17: ='Cập nhật trạng thái món ăn'!$F$4 -> 12 | E17: Khiêm
A18: 14 | B18: Thông báo món đã hoàn thành | C18: Thông báo món đã hoàn thành | D18: ='Thông báo món đã hoàn thành'!$F$4 -> 2 | E18: Khiêm
A19: 15 | B19: Cập nhật trạng thái phục vụ món | C19: Cập nhật trạng thái phục vụ món | D19: ='Cập nhật trạng thái phục vụ món'!$F$4 -> 19 | E19: Khiêm
A20: 16 | B20: Quản lý đơn hàng (Staff) | C20: Quản lý đơn hàng (Staff) | D20: ='Quản lý đơn hàng (Staff)'!$F$4 -> 15 | E20: Khiêm
D21: =SUM(D5:D20) -> 268

Sheet Báo cáo kiểm tra
A1: Báo cáo thử nghiệm
A3: Tên dự án | B3: Website bán thời trang | E3: Creator | H3: Phạm Nguyễn Đình huy
E4: Người đánh giá/phê duyệt | H4: Cả nhóm
E5: Ngày triển khai | H5: 44114
A6: Ghi chú | B6: Tính năng đang chờ xử lý :
C7: Hoàn thành | E7: Lỗi | G7: Chưa Kiểm tra | I7: Bị chặn | K7: Số trường hợp thử nghiệm | M7: % Thành công | O7: % Coverage
A9: STT | B9: Tên hiển thị | C9: Vòng 1 | D9: Vòng 2 | E9: Vòng 1 | F9: Vòng 2 | G9: Vòng 1 | H9: Vòng 2 | I9: Vòng 1 | J9: Vòng 2 | K9: Vòng 1 | L9: Vòng 2 | M9: Vòng 1 | N9: Vòng 2 | O9: Vòng 1 | P9: Vòng 2
A10: 1 | B10: Đăng nhập | C10: 15 | D10: 15 | E10: 0 | F10: ='[1]Show Bus Routes List'!C6 -> 0 | G10: ='[1]Show Bus Routes List'!D5 -> 0 | H10: ='[1]Show Bus Routes List'!D6 -> 0 | I10: ='[1]Show Bus Routes List'!E5 -> 0 | J10: ='[1]Show Bus Routes List'!E6 -> 0 | K10: 15 | L10: 15 | M10: =ROUND(C10*100/K10,1) -> 100 | N10: =ROUND(D10*100/L10,1) -> 100 | O10: =ROUND((C10+E10)*100/K10,1) -> 100 | P10: =ROUND((D10+F10)*100/L10,1) -> 100
A11: 2 | B11: Quản lý sản phẩm
A12: 3 | B12: Quản lý danh mục | C12: 12 | D12: 12 | E12: 0 | F12: ='[1]Show Bus Stops List'!C6 -> 0 | G12: ='[1]Show Bus Stops List'!D5 -> 0 | H12: ='[1]Show Bus Stops List'!D6 -> 0 | I12: ='[1]Show Bus Stops List'!E5 -> 0 | J12: ='[1]Show Bus Stops List'!E6 -> 0 | K12: 12 | L12: 12 | M12: =ROUND(C12*100/K12,1) -> 100 | N12: =ROUND(D12*100/L12,1) -> 100 | O12: =ROUND((C12+E12)*100/K12,1) -> 100 | P12: =ROUND((D12+F12)*100/L12,1) -> 100
A13: 4 | B13: Quản lý nhãn hiệu
A14: 5 | B14: Quản lý mã khuyến mãi | C14: 8 | D14: 8 | E14: =#REF! -> #REF! | F14: =#REF! -> #REF! | G14: =#REF! -> #REF! | H14: =#REF! -> #REF! | I14: =#REF! -> #REF! | J14: =#REF! -> #REF! | K14: 4 | L14: 4 | M14: =ROUND(C14*100/K14,1) -> 200 | N14: =ROUND(D14*100/L14,1) -> 200 | O14: =ROUND((C14+E14)*100/K14,1) -> #REF! | P14: =ROUND((D14+F14)*100/L14,1) -> #REF!
A15: 6 | B15: Quản lý hóa đơn
A16: 7 | B16: Quản lý tài khoản người dùng | C16: 15 | D16: 15 | E16: 0 | F16: 0 | G16: 0 | H16: 0 | I16: 0 | J16: 0 | K16: 15 | L16: 15 | M16: =ROUND(C16*100/K16,1) -> 100 | N16: 100 | O16: 100 | P16: 100
A17: 8 | B17: Quản lý bài viết | C17: 20 | D17: 20 | E17: =#REF! -> #REF! | F17: =#REF! -> #REF! | G17: =#REF! -> #REF! | H17: =#REF! -> #REF! | I17: =#REF! -> #REF! | J17: =#REF! -> #REF! | K17: 20 | L17: 20 | M17: =ROUND(C17*100/K17,1) -> 100 | N17: =ROUND(D17*100/L17,1) -> 100 | O17: =ROUND((C17+E17)*100/K17,1) -> #REF! | P17: =ROUND((D17+F17)*100/L17,1) -> #REF!
A18: 9 | B18: Quản lý bình luận | C18: 27 | D18: 27 | E18: =#REF! -> #REF! | F18: 0 | G18: =#REF! -> #REF! | H18: =#REF! -> #REF! | I18: =#REF! -> #REF! | J18: 0 | K18: 27 | L18: 27 | M18: =ROUND(C18*100/K18,1) -> 100 | N18: =ROUND(D18*100/L18,1) -> 100 | O18: =ROUND((C18+E18)*100/K18,1) -> #REF! | P18: =ROUND((D18+F18)*100/L18,1) -> 100
A19: 10 | B19: Tìm kiếm | C19: 17 | D19: 17 | E19: 0 | F19: =#REF! -> #REF! | G19: 0 | H19: 0 | I19: 0 | J19: =#REF! -> #REF! | K19: 17 | L19: 17 | M19: =ROUND(C19*100/K19,1) -> 100 | N19: =ROUND(D19*100/L19,1) -> 100 | O19: =ROUND((C19+E19)*100/K19,1) -> 100 | P19: =ROUND((D19+F19)*100/L19,1) -> #REF!
A20: 11 | B20: Quản lý thống kê | C20: 18 | D20: 18 | E20: =#REF! -> #REF! | F20: 0 | G20: =#REF! -> #REF! | H20: =#REF! -> #REF! | I20: =#REF! -> #REF! | J20: 0 | K20: 18 | L20: 18 | M20: =ROUND(C20*100/K20,1) -> 100 | N20: =ROUND(D20*100/L20,1) -> 100 | O20: =ROUND((C20+E20)*100/K20,1) -> #REF! | P20: =ROUND((D20+F20)*100/L20,1) -> 100
B21: Sub total | C21: =SUM(C10:C20) -> 132 | D21: =SUM(D10:D20) -> 132 | E21: =SUM(E10:E20) -> #REF! | F21: =SUM(F10:F20) -> #REF! | G21: =SUM(G10:G20) -> #REF! | H21: =SUM(H10:H20) -> #REF! | I21: =SUM(I10:I20) -> #REF! | J21: =SUM(J10:J20) -> #REF! | ... P21: =SUM(P10:P20) -> #REF!
C22: Vòng 1 | D22: Vòng2
B23: Kiểm tra phủ sóng | C23: =ROUND((C21+E21)*100/K21,1) -> #REF! | D23: =ROUND((D21+F21)*100/L21,1) -> #REF! | E23: %
B24: Kiểm tra thành công phủ sống | C24: =ROUND(C21*100/K21,1) -> 103.1 | D24: =ROUND(D21*100/L21,1) -> 103.1 | E24: %

Sheet Đăng nhập (Nhân viên & Khách)
A1: Project Name | B1: XÂY DỰNG HỆ THỐNG QUẢN LÝ NHÀ HÀNG THEO MÔ HÌNH TƯƠNG TÁC SỐ ĐA KÊNH
A2: Module Code | B2: Đăng nhập (Nhân viên & Khách)
B3: Hoàn thành | C3: Lỗi | D3: Chưa kiểm tra | E3: Bị chặn | F3: Tổng số trường hợp thử nghiệm
A4: Round 1 | B4: =COUNTIF(G12:G88,"Passed") -> 17 | C4: =COUNTIF(G12:G88,"Failed") -> 0 | D4: =COUNTIF(G12:G29,"Untested") -> 0 | E4: =COUNTIF(G12:G29,"Blocked") -> 0 | F4: =SUM(B4:C4) -> 17
A5: Round 2 | B5: =COUNTIF(J12:J88,"Passed") -> 17 | C5: =COUNTIF(J12:J88,"Failed") -> 0 | D5: =COUNTIF(J12:J29,"Untested") -> 0 | E5: =COUNTIF(J12:J29,"Blocked") -> 0 | F5: =SUM(B5:C5) -> 17
A8: Test Case ID | B8: Mô tả | C8: Hành động | D8: Điều kiện tiên quyết | E8: Kết quả mong đợi | F8: Kết quả thực tế | G8: Kết quả | J8: Kết quả | M8: Chú thích
G9: Vòng 1 | J9: Vòng 2
G10: Trạng thái | H10: Ngày kiểm tra | I10: Người kiểm tra | J10: Trạng thái | K10: Ngày kiểm tra | L10: Người kiểm tra
A11: GUI_SHOW - Trang đăng nhập
A12: GUI-DN01 | B12: [Label/Tiêu đề] Hàng chữ "Đăng nhập EatEase" | C12: Đứng tại trang Đăng nhập, quan sát tiêu đề | D12: Truy cập vào hệ thống (/login) | E12: Hiển thị rõ, đúng font chữ, màu sắc hài hòa | F12: Hiển thị rõ, đúng font chữ, màu sắc hài hòa | G12: Passed | H12: 46121 | I12: Ngọc | J12: Passed | K12: 46124 | L12: Ngọc
A13: GUI-DN02 | B13: [Email] Textbox | C13: Quan sát ô nhập Email | D13: Truy cập vào hệ thống | E13: Text color: Đen (hoặc trắng nếu dark mode) Status: enable | F13: Text color: Đen (hoặc trắng nếu dark mode) Status: enable | G13: Passed | H13: 46121 | I13: Ngọc | J13: Passed | K13: 46124 | L13: Ngọc
A14: GUI-DN03 | B14: [Mật khẩu] Textbox | C14: Quan sát ô nhập Mật khẩu | D14: Mật khẩu Truy cập vào hệ thống | E14: Text color: Đen/trắng Trạng thái nhập bị ẩn đi (ký tự *) Status: enable | F14: Text color: Đen/trắng Trạng thái nhập bị ẩn đi (ký tự *) Status: enable | G14: Passed | H14: 46121 | I14: Ngọc | J14: Passed | K14: 46124 | L14: Ngọc
A15: GUI-DN04 | B15: [Icon Con Mắt] Password Toggle | C15: Nhấp vào icon con mắt ở ô mật khẩu | D15: Đã nhập ký tự vào ô mật khẩu | E15: Ký tự mật khẩu hiện lên dạng văn bản thường. Nhấp lần nữa bị ẩn đi. | F15: Ký tự mật khẩu hiện lên dạng văn bản thường. Nhấp lần nữa bị ẩn đi. | G15: Passed | H15: 46121 | I15: Ngọc | J15: Passed | K15: 46124 | L15: Ngọc
A16: GUI-DN05 | B16: [Quên mật khẩu] Link | C16: Quan sát link "Quên mật khẩu" | D16: Truy cập vào hệ thống | E16: Text color: nổi bật, đổi màu khi hover Status: enable | F16: Text color: nổi bật, đổi màu khi hover Status: enable | G16: Passed | H16: 46121 | I16: Ngọc | J16: Passed | K16: 46124 | L16: Ngọc
A17: GUI-DN06 | B17: Đăng nhập] Button | C17: Quan sát nút Đăng nhập chính | D17: Truy cập vào hệ thống | E17: Status: enable | F17: Status: enable | G17: Passed | H17: 46121 | I17: Ngọc | J17: Passed | K17: 46124 | L17: Ngọc
A18: GUI-DN07 | B18: [Google/Facebook] Buttons | C18: Quan sát nút Đăng nhập mạng xã hội | D18: Truy cập vào hệ thống | E18: Nút hiển thị đúng icon Google (Đỏ) và Facebook (Xanh) Status: enable | F18: Nút hiển thị đúng icon Google (Đỏ) và Facebook (Xanh) Status: enable | G18: Passed | H18: 46121 | I18: Ngọc | J18: Passed | K18: 46124 | L18: Ngọc
A19: FUNCTION_SHOW - Trang đăng nhập
A20: FUNC-DN01 | B20: Đăng nhập thành công với tài khoản có sẵn | C20: 1. Nhập email và password đúng 2. Click button Đăng nhập | D20: Trình duyệt ở trang /login. Tài khoản đã có trong DB. | E20: Chuyển hướng thành công sang trang chủ (/) hoặc bảng điều khiển. Trạng thái Loading hiển thị lúc chờ. | F20: Chuyển hướng thành công sang trang chủ (/) hoặc bảng điều khiển. Trạng thái Loading hiển thị lúc chờ. | G20: Passed | H20: 46121 | I20: Ngọc | J20: Passed | K20: 46124 | L20: Ngọc
A21: FUNC-DN02 | B21: Đăng nhập thất bại sai Password | C21: 1. Nhập email đúng, password sai 2. Click Đăng nhập | D21: Truy cập vào hệ thống | E21: Hệ thống thông báo lỗi: "Mật khẩu không chính xác!" | F21: Hệ thống thông báo lỗi: "Mật khẩu không chính xác!" | G21: Passed | H21: 46121 | I21: Ngọc | J21: Passed | K21: 46124 | L21: Ngọc
A22: FUNC-DN03 | B22: Đăng nhập thất bại sai Email | C22: 1. Nhập email chưa từng đăng ký và password 2. Click Đăng nhập | D22: Truy cập vào hệ thống | E22: Hệ thống thông báo lỗi: "Email không tồn tại, vui lòng đăng ký" | F22: Hệ thống thông báo lỗi: "Email không tồn tại, vui lòng đăng ký" | G22: Passed | H22: 46121 | I22: Ngọc | J22: Passed | K22: 46124 | L22: Ngọc
A23: FUNC-DN04 | B23: Để trống trường Mật khẩu | C23: 1. Nhập email 2. Không nhập mật khẩu 3. Click Đăng nhập | D23: Truy cập vào hệ thống | E23: Hệ thống chặn gọi API, hiện thông báo: "Vui lòng nhập đầy đủ thông tin" | F23: Hệ thống chặn gọi API, hiện thông báo: "Vui lòng nhập đầy đủ thông tin" | G23: Passed | H23: 46121 | I23: Ngọc | J23: Passed | K23: 46124 | L23: Ngọc
A24: FUNC-DN05 | B24: Để trống trường Email | C24: 1. Để ô Email trống 2. Nhập mật khẩu 3. Click Đăng nhập | D24: Truy cập vào hệ thống | E24: Hệ thống hiện thông báo: "Vui lòng nhập đầy đủ thông tin" | F24: Hệ thống hiện thông báo: "Vui lòng nhập đầy đủ thông tin" | G24: Passed | H24: 46121 | I24: Ngọc | J24: Passed | K24: 46124 | L24: Ngọc
A25: FUNC-DN06 | B25: Validation sai định dạng Email | C25: 1. Nhập vào ô email cụm: abcxyz 2. Nhập password 3. Click Đăng nhập | D25: Truy cập vào hệ thống | E25: Hệ thống hiện lỗi validation: "Vui lòng nhập địa chỉ email hợp lệ" (do không có @) | F25: Hệ thống hiện lỗi validation: "Vui lòng nhập địa chỉ email hợp lệ" (do không có @) | G25: Passed | H25: 46121 | I25: Ngọc | J25: Passed | K25: 46124 | L25: Ngọc
A26: FUNC-DN07 | B26: Chuyển sang Quên Mật Khẩu | C26: 1. Click vào chữ "Bạn quên mật khẩu?" | D26: Truy cập vào hệ thống | E26: Hệ thống chuyển hướng sang trang /forgot-password thành công. | F26: 1. Nhập vào ô email cụm: abcxyz 2. Nhập password 3. Click Đăng nhập | G26: Passed | H26: 46121 | I26: Ngọc | J26: Passed | K26: 46124 | L26: Ngọc
A27: FUNC-DN08 | B27: Đăng nhập bằng Google thành công | C27: 1. Click nút "Google" 2. Chọn tài khoản Gmail trên popup | D27: Truy cập vào hệ thống | E27: Cửa sổ popup xử lý xong, hệ thống thông báo "Đăng nhập Google thành công" và vào trang chủ. | F27: Cửa sổ popup xử lý xong, hệ thống thông báo "Đăng nhập Google thành công" và vào trang chủ. | G27: Passed | H27: 46121 | I27: Ngọc | J27: Passed | K27: 46124 | L27: Ngọc
A28: FUNC-DN09 | B28: Đăng nhập bằng Facebook thành công | C28: 1. Click nút "Facebook" 2. Đồng ý quyền ứng dụng từ Facebook | D28: App ID đã thiết lập | E28: Cửa sổ popup Facebook nhận diện, thông báo "Đăng nhập Facebook thành công" và vào trang chủ. | F28: Cửa sổ popup Facebook nhận diện, thông báo "Đăng nhập Facebook thành công" và vào trang chủ. | G28: Passed | H28: 46121 | I28: Ngọc | J28: Passed | K28: 46124 | L28: Ngọc
A29: FUNC-DN10 | B29: Cancel bỏ qua đăng nhập Mạng xã hội | C29: 1. Click nút Google/Facebook 2. Tắt popup không chọn gì | D29: Truy cập vào hệ thống | E29: Hệ thống không lỗi, về lại trạng thái chờ ở giao diện Login bình thường. | F29: Hệ thống không lỗi, về lại trạng thái chờ ở giao diện Login bình thường. | G29: Passed | H29: 46121 | I29: Ngọc | J29: Passed | K29: 46124 | L29: Ngọc

Sheet Đăng ký tài khoản khách hàng
A1: Project Name | B1: XÂY DỰNG HỆ THỐNG QUẢN LÝ NHÀ HÀNG THEO MÔ HÌNH TƯƠNG TÁC SỐ ĐA KÊNH
A2: Module Code | B2: Đăng ký tài khoản khách hàng
B3: Hoàn thành | C3: Lỗi | D3: Chưa kiểm tra | E3: Bị chặn | F3: Tổng số trường hợp thử nghiệm
A4: Round 1 | B4: =COUNTIF(G12:G88,"Passed") -> 17 | C4: =COUNTIF(G12:G88,"Failed") -> 0 | D4: =COUNTIF(G12:G29,"Untested") -> 0 | E4: =COUNTIF(G12:G29,"Blocked") -> 0 | F4: =SUM(B4:C4) -> 17
A5: Round 2 | B5: =COUNTIF(J12:J88,"Passed") -> 17 | C5: =COUNTIF(J12:J88,"Failed") -> 0 | D5: =COUNTIF(J12:J29,"Untested") -> 0 | E5: =COUNTIF(J12:J29,"Blocked") -> 0 | F5: =SUM(B5:C5) -> 17
A8: Test Case ID | B8: Mô tả | C8: Hành động | D8: Điều kiện tiên quyết | E8: Kết quả mong đợi | F8: Kết quả thực tế | G8: Kết quả | J8: Kết quả | M8: Chú thích
G9: Vòng 1 | J9: Vòng 2
G10: Trạng thái | H10: Ngày kiểm tra | I10: Người kiểm tra | J10: Trạng thái | K10: Ngày kiểm tra | L10: Người kiểm tra
A11: GUI_SHOW - Đăng ký
A12: GUI-DK01 | B12: [Label/Tiêu đề] Hàng chữ "Tạo Tài Khoản" | C12: Đứng tại màn hình Đăng ký, quan sát tiêu đề | D12: Truy cập vào hệ thống (/register) | E12: Hiển thị rõ, font chữ đậm, canh giữa | F12: Hiển thị rõ, font chữ đậm, canh giữa | G12: Passed | H12: 46121 | I12: Ngọc | J12: Passed | K12: 46124 | L12: Ngọc
A13: GUI-DK02 | B13: [Tên người dùng] Textbox | C13: Quan sát ô nhập Tên người dùng | D13: Truy cập vào hệ thống | E13: Text color: Đen (trắng nếu dark mode). Placeholder: "Nhập tên của bạn" Status: enable | F13: Text color: Đen (trắng nếu dark mode). Placeholder: "Nhập tên của bạn" Status: enable | G13: Passed | H13: 46121 | I13: Ngọc | J13: Passed | K13: 46124 | L13: Ngọc
A14: GUI-DK03 | B14: [Email] Textbox | C14: Quan sát ô nhập Email | D14: Truy cập vào hệ thống | E14: Placeholder: " m@example.com " Status: enable | F14: Placeholder: " m@example.com " Status: enable | G14: Passed | H14: 46121 | I14: Ngọc | J14: Passed | K14: 46124 | L14: Ngọc
A15: GUI-DK04 | B15: [Số điện thoại] Textbox | C15: Quan sát ô nhập Số điện thoại | D15: Truy cập vào hệ thống | E15: Placeholder: "Nhập số điện thoại của bạn" Status: enable | F15: Placeholder: "Nhập số điện thoại của bạn" Status: enable | G15: Passed | H15: 46121 | I15: Ngọc | J15: Passed | K15: 46124 | L15: Ngọc
A16: GUI-DK05 | B16: [Mật khẩu & Xác nhận] Textboxes | C16: Quan sát 2 ô nhập Mật khẩu | D16: Truy cập vào hệ thống | E16: Text ẩn đi dạng *. Cả 2 ô đều có icon con mắt bên cạnh phải. Status: enable | F16: Text ẩn đi dạng *. Cả 2 ô đều có icon con mắt bên cạnh phải. Status: enable | G16: Passed | H16: 46121 | I16: Ngọc | J16: Passed | K16: 46124 | L16: Ngọc
A17: GUI-DK06 | B17: [Icon Con Mắt] Toggle | C17: Nhấp vào icon con mắt ở các ô mật khẩu | D17: Đã nhập ký tự vào ô | E17: Text mật khẩu hiện lên, icon chuyển sang EyeOff. Nhấp lại thì ẩn đi. | F17: Text mật khẩu hiện lên, icon chuyển sang EyeOff. Nhấp lại thì ẩn đi. | G17: Passed | H17: 46121 | I17: Ngọc | J17: Passed | K17: 46124 | L17: Ngọc
A18: GUI-DK07 | B18: [Đăng ký] Button | C18: Quan sát nút hành động chính | D18: Truy cập vào hệ thống | E18: Nút bự hiển thị chữ "Đăng ký" Status: enable | F18: Nút bự hiển thị chữ "Đăng ký" Status: enable | G18: Passed | H18: 46121 | I18: Ngọc | J18: Passed | K18: 46124 | L18: Ngọc
A19: FUNCTION_SHOW - Đăng ký
A20: FUNC-DK01 | B20: Đăng ký tài khoản thành công | C20: 1. Nhập Tên, Email, SĐT, Mật khẩu, Xác nhận (đúng chuẩn) 2. Click button "Đăng ký" | D20: Email chưa từng được đăng ký trong CSDL. | E20: Hệ thống thông báo thành công, chuyển hướng người dùng sang trang /registration-success | F20: Hệ thống thông báo thanh công, chuyển hướng người dùng sang trang /registration-success | G20: Passed | H20: 46121 | I20: Ngọc | J20: Passed | K20: 46124 | L20: Ngọc
A21: FUNC-DK02 | B21: Đăng ký thất bại do trùng Email | C21: 1. Nhập thông tin đầy đủ, sử dụng Email đã có trong hệ thống 2. Click Đăng ký | D21: Email đã được lưu ở CSDL | E21: Hệ thống chặn đăng ký, trả về lỗi "Email đã tồn tại" | F21: Hệ thống chặn đăng ký, trả về lỗi "Email đã tồn tại" | G21: Passed | H21: 46121 | I21: Ngọc | J21: Passed | K21: 46124 | L21: Ngọc
A22: FUNC-DK03 | B22: Để trống 1 trường dữ liệu | C22: 1. Điền 4 trường 2. Bỏ trống 1 trường (VD: Email hoặc SĐT) 3. Click Đăng ký | D22: Truy cập vào hệ thống | E22: Hệ thống hiện thông báo: "Vui lòng nhập đầy đủ thông tin." | F22: Hệ thống hiện thông báo: "Vui lòng nhập đầy đủ thông tin." | G22: Passed | H22: 46121 | I22: Ngọc | J22: Passed | K22: 46124 | L22: Ngọc
A23: FUNC-DK04 | B23: Email sai định dạng | C23: 1. Nhập email: testabc 2. Nhập các trường còn lại đúng 3. Click Đăng ký | D23: Truy cập vào hệ thống | E23: Hệ thống chặn và báo: "Vui lòng nhập địa chỉ email hợp lệ" | F23: Hệ thống chặn và báo: "Vui lòng nhập địa chỉ email hợp lệ" | G23: Passed | H23: 46121 | I23: Ngọc | J23: Passed | K23: 46124 | L23: Ngọc
A24: FUNC-DK05 | B24: Số điện thoại sai định dạng | C24: 1. Nhập SĐT không bắt đầu bằng số 0 hoặc thiếu số 2. Nhập các trường khác đúng 3. Click Đăng ký | D24: Truy cập vào hệ thống | E24: Hệ thống chặn và báo lỗi: "Số điện thoại không hợp lệ" | F24: Hệ thống chặn và báo lỗi: "Số điện thoại không hợp lệ" | G24: Passed | H24: 46121 | I24: Ngọc | J24: Passed | K24: 46124 | L24: Ngọc
A25: FUNC-DK06 | B25: Mật khẩu chung quá ngắn | C25: 1. Nhập mật khẩu < 6 ký tự (12345) 2. Click Đăng ký | D25: Truy cập vào hệ thống | E25: cập vào hệ thống Hệ thống chặn đăng ký, báo lỗi: "Mật khẩu phải có ít nhất 6 ký tự" | F25: cập vào hệ thống Hệ thống chặn đăng ký, báo lỗi: "Mật khẩu phải có ít nhất 6 ký tự" | G25: Passed | H25: 46121 | I25: Ngọc | J25: Passed | K25: 46124 | L25: Ngọc
A26: FUNC-DK07 | B26: Xác nhận mật khẩu không khớp | C26: 1. Nhập MK: 123456 2. Nhập Xác nhận MK: 123123 3. Click Đăng ký | D26: Truy cập vào hệ thống | E26: Hệ thống chặn và báo lỗi: "Mật khẩu và mật khẩu xác nhận phải giống nhau" | F26: Hệ thống chặn và báo lỗi: "Mật khẩu và mật khẩu xác nhận phải giống nhau" | G26: Passed | H26: 46121 | I26: Ngọc | J26: Passed | K26: 46124 | L26: Ngọc
A27: FUNC-DK08 | B27: Chuyển sang Đăng nhập | C27: 1. Click vào đường link "Đăng nhập" ở cuối form | D27: Truy cập vào hệ thống | E27: Form Đăng ký biến mất, truy cập thành công vào màn hình /login | F27: Form Đăng ký biến mất, truy cập thành công vào màn hình /login | G27: Passed | H27: 46121 | I27: Ngọc | J27: Passed | K27: 46124 | L27: Ngọc
A28: FUNC-DK09 | B28: Đăng ký nhanh bằng Google | C28: 1. Click button "Google" 2. Cấp quyền đăng nhập | D28: Truy cập vào hệ thống | E28: Pop-up xử lý thành công, tài khoản mới được tự động tạo, tự login và chuyển hướng vào Trang chủ. | F28: Pop-up xử lý thành công, tài khoản mới được tự động tạo, tự login và chuyển hướng vào Trang chủ. | G28: Passed | H28: 46121 | I28: Ngọc | J28: Passed | K28: 46124 | L28: Ngọc
A29: FUNC-DK10 | B29: Đăng ký nhanh bằng Facebook | C29: 1. Click button "Facebook" 2. Cấp quyền cho app | D29: Truy cập vào hệ thống | E29: Pop-up xử lý thành công, tài khoản tự động khởi tạo, báo "Đăng ký và đăng nhập Facebook thành công". | F29: Pop-up xử lý thành công, tài khoản tự động khởi tạo, báo "Đăng ký và đăng nhập Facebook thành công". | G29: Passed | H29: 46121 | I29: Ngọc | J29: Passed | K29: 46124 | L29: Ngọc

Sheet Quản lý danh mục món ăn
A1: Project Name | B1: XÂY DỰNG HỆ THỐNG QUẢN LÝ NHÀ HÀNG THEO MÔ HÌNH TƯƠNG TÁC SỐ ĐA KÊNH
A2: Module Code | B2: Quản lý danh mục món ăn
B3: Hoàn thành | C3: Lỗi | D3: Chưa kiểm tra | E3: Bị chặn | F3: Tổng số trường hợp thử nghiệm
A4: Round 1 | B4: =COUNTIF(G20:G82,"Passed") -> 22 | C4: =COUNTIF(G20:G82,"Failed") -> 0 | D4: =COUNTIF(G20:G29,"Untested") -> 0 | E4: =COUNTIF(G20:G29,"Blocked") -> 0 | F4: =SUM(B4:C4) -> 22
A5: Round 2 | B5: =COUNTIF(J20:J82,"Passed") -> 22 | C5: =COUNTIF(J20:J82,"Failed") -> 0 | D5: =COUNTIF(J20:J29,"Untested") -> 0 | E5: =COUNTIF(J20:J29,"Blocked") -> 0 | F5: =SUM(B5:C5) -> 22
A8: Test Case ID | B8: Mô tả | C8: Hành động | D8: Điều kiện tiên quyết | E8: Kết quả mong đợi | F8: Kết quả thực tế | G8: Kết quả | J8: Kết quả | M8: Chú thích
G9: Vòng 1 | J9: Vòng 2
G10: Trạng thái | H10: Ngày kiểm tra | I10: Người kiểm tra | J10: Trạng thái | K10: Ngày kiểm tra | L10: Người kiểm tra
A11: GUI_SHOW - Giao diện trang Quản lý danh mục
A12: GUI-CAT01 | B12: Hiển thị danh sách danh mục món ăn | C12: 1. Admin đăng nhập vào hệ thống 2. Admin truy cập menu "Quản lý danh mục món ăn" 3. Hệ thống tải và hiển thị danh sách danh mục | D12: Admin đã đăng nhập vào hệ thống với quyền quản lý danh mục Hệ thống có ít nhất 1 danh mục món ăn trong cơ sở dữ liệu | E12: 1. Hiển thị danh sách đầy đủ các danh mục món ăn chưa bị xóa 2. Mỗi danh mục hiển thị: tên danh mục, hình ảnh, mô tả (nếu có), ngày tạo 3. Hiển thị các nút chức năng: "Thêm danh mục", "Sửa", "Xóa" cho mỗi danh mục | F12: 1. Hiển thị danh sách đầy đủ các danh mục món ăn chưa bị xóa 2. Mỗi danh mục hiển thị: tên danh mục, hình ảnh, mô tả (nếu có), ngày tạo 3. Hiển thị các nút chức năng: "Thêm danh mục", "Sửa", "Xóa" cho mỗi danh mục | G12: Passed | H12: 46121 | I12: Hiếu | J12: Passed | K12: 46124 | L12: Hiếu
A13: GUI-CAT02 | B13: Hiển thị hình ảnh danh mục | C13: 1. Admin truy cập trang quản lý danh mục món ăn 2. Quan sát hình ảnh của các danh mục trong danh sách | D13: Admin đã đăng nhập vào hệ thống | E13: 1. Hình ảnh danh mục hiển thị đúng, rõ nét 2. Hình ảnh có kích thước phù hợp, không bị méo hoặc vỡ | F13: 1. Hình ảnh danh mục hiển thị đúng, rõ nét 2. Hình ảnh có kích thước phù hợp, không bị méo hoặc vỡ | G13: Passed | H13: 46121 | I13: Hiếu | J13: Passed | K13: 46124 | L13: Hiếu
A14: GUI-CAT03 | B14: Hiển thị các nút chức năng | C14: 1. Admin truy cập trang quản lý danh mục món ăn 2. Quan sát các nút chức năng trên giao diện | D14: Admin đã đăng nhập vào hệ thống với quyền quản lý danh mục Hệ thống có ít nhất 1 danh mục món ăn trong cơ sở dữ liệu | E14: 1. Hiển thị nút "Thêm danh mục mới" ở vị trí dễ nhìn (góc trên bên phải hoặc trên cùng) 2. Mỗi danh mục có nút "Sửa" và "Xóa" với icon rõ ràng | F14: 1. Hiển thị nút "Thêm danh mục mới" ở vị trí dễ nhìn (góc trên bên phải hoặc trên cùng) 2. Mỗi danh mục có nút "Sửa" và "Xóa" với icon rõ ràng | G14: Passed | H14: 46121 | I14: Hiếu | J14: Passed | K14: 46124 | L14: Hiếu
A15: GUI-CAT04 | B15: Hiển thị trạng thái không có dữ liệu | C15: 1. Admin đăng nhập vào hệ thống 2. Admin truy cập trang quản lý danh mục món ăn khi chưa có danh mục nào | D15: Admin đã đăng nhập vào hệ thống Hệ thống chưa có danh mục món ăn nào (hoặc tất cả đã bị xóa) | E15: Hiển thị thông báo empty state: "Chưa có danh mục món ăn nào" | F15: Hiển thị thông báo empty state: "Chưa có danh mục món ăn nào" | G15: Passed | H15: 46121 | I15: Hiếu | J15: Passed | K15: 46124 | L15: Hiếu
A16: GUI-CAT05 | B16: Hiển thị form thêm danh mục | C16: 1. Admin truy cập trang quản lý danh mục món ăn 2. Admin nhấn nút "Thêm danh mục mới" 3. Quan sát form thêm danh mục | D16: Admin đã đăng nhập vào hệ thống | E16: 1. Hiển thị modal hoặc form thêm danh mục với các trường 2. Hiển thị nút "Lưu" và "Hủy" 3. Các trường bắt buộc có dấu * màu đỏ | F16: 1. Hiển thị modal hoặc form thêm danh mục với các trường 2. Hiển thị nút "Lưu" và "Hủy" 3. Các trường bắt buộc có dấu * màu đỏ | G16: Passed | H16: 46121 | I16: Hiếu | J16: Passed | K16: 46124 | L16: Hiếu
A17: GUI-CAT06 | B17: Hiển thị form sửa danh mục | C17: 1. Admin truy cập trang quản lý danh mục món ăn 2. Admin nhấn nút "Sửa" trên một danh mục 3. Quan sát form sửa danh mục | D17: Admin đã đăng nhập vào hệ thống Có ít nhất 1 danh mục trong hệ thống | E17: 1. Hiển thị modal hoặc form sửa danh mục 2. Các trường được điền sẵn thông tin hiện tại của danh mục 3. Hiển thị preview hình ảnh hiện tại 4. Có thể thay đổi hình ảnh bằng cách upload ảnh mới 5. Hiển thị nút "Lưu thay đổi" và "Hủy" | F17: 1. Hiển thị modal hoặc form sửa danh mục 2. Các trường được điền sẵn thông tin hiện tại của danh mục 3. Hiển thị preview hình ảnh hiện tại 4. Có thể thay đổi hình ảnh bằng cách upload ảnh mới 5. Hiển thị nút "Lưu thay đổi" và "Hủy" | G17: Passed | H17: 46121 | I17: Hiếu | J17: Passed | K17: 46124 | L17: Hiếu
A18: GUI-CAT07 | B18: Hiển thị dialog xác nhận xóa | C18: 1. Admin truy cập trang quản lý danh mục món ăn 2. Admin nhấn nút "Xóa" trên một danh mục 3. Quan sát dialog xác nhận | D18: Admin đã đăng nhập vào hệ thống Có ít nhất 1 danh mục trong hệ thống | E18: 1. Hiển thị dialog xác nhận 2. Hiển thị tên danh mục sẽ bị xóa 3. Dialog có thể đóng bằng cách nhấn nút Hủy hoặc click ra ngoài | F18: 1. Hiển thị dialog xác nhận 2. Hiển thị tên danh mục sẽ bị xóa 3. Dialog có thể đóng bằng cách nhấn nút Hủy hoặc click ra ngoài | G18: Passed | H18: 46121 | I18: Hiếu | J18: Passed | K18: 46124 | L18: Hiếu
A19: GUI-CAT08 | B19: Tab "Danh mục đã xóa" | C19: 1. Admin truy cập trang quản lý danh mục món ăn 2. Admin nhấn vào tab "Danh mục đã xóa" 3. Quan sát danh sách danh mục đã xóa | D19: Admin đã đăng nhập vào hệ thống Có ít nhất 1 danh mục đã bị xóa (soft delete) | E19: 1. Hiển thị tab "Danh mục đã xóa" rõ ràng 2. Danh sách hiển thị các danh mục đã bị xóa với thông tin: tên, hình ảnh, ngày xóa 3. Mỗi danh mục có 2 nút: "Khôi phục" và "Xóa vĩnh viễn" | F19: 1. Hiển thị tab "Danh mục đã xóa" rõ ràng 2. Danh sách hiển thị các danh mục đã bị xóa với thông tin: tên, hình ảnh, ngày xóa 3. Mỗi danh mục có 2 nút: "Khôi phục" và "Xóa vĩnh viễn" | G19: Passed | H19: 46121 | I19: Hiếu | J19: Passed | K19: 46124 | L19: Hiếu
A20: FUNCTION_SHOW - Chức năng Thêm danh mục
A21: FUNC-CAT01 | B21: Thêm danh mục hợp lệ | C21: 1. Admin đăng nhập vào hệ thống 2. Admin truy cập trang quản lý danh mục món ăn 3. Admin nhập đầy đủ các thông tin | D21: Admin đã đăng nhập vào hệ thống với quyền quản lý danh mục Tên danh mục chưa tồn tại trong hệ thống | E21: 1. Hệ thống hiển thị thông báo: "Thêm danh mục thành công" 2. Danh mục mới xuất hiện trong danh sách ở vị trí đầu tiên | F21: 1. Hệ thống hiển thị thông báo: "Thêm danh mục thành công" 2. Danh mục mới xuất hiện trong danh sách ở vị trí đầu tiên | G21: Passed | H21: 46121 | I21: Hiếu | J21: Passed | K21: 46124 | L21: Hiếu
A22: FUNC-CAT02 | B22: Thêm danh mục - Bỏ trống tên | C22: 1. Admin đăng nhập vào hệ thống 2. Admin truy cập trang quản lý danh mục món ăn 3. Admin nhấn nút "Thêm danh mục mới" 4. Admin để trống trường "Tên danh mục" | D22: Admin đã đăng nhập vào hệ thống | E22: 1. Hệ thống hiển thị thông báo lỗi: "Vui lòng điền đầy đủ các trường bắt buộc" 2. Trường "Tên danh mục" được highlight màu đỏ | F22: 1. Hệ thống hiển thị thông báo lỗi: "Vui lòng điền đầy đủ các trường bắt buộc" 2. Trường "Tên danh mục" được highlight màu đỏ 3. Form không đóng, dữ liệu không được lưu | G22: Passed | H22: 46121 | I22: Hiếu | J22: Passed | K22: 46124 | L22: Hiếu
A23: FUNC-CAT03 | B23: Thêm danh mục - Tên quá dài (>100 ký tự) | C23: 1. Admin đăng nhập vào hệ thống 2. Admin truy cập trang quản lý danh mục món ăn 3. Admin nhấn nút "Thêm danh mục mới" 4. Admin nhập tên danh mục dài 101 ký tự | D23: Admin đã đăng nhập vào hệ thống | E23: 1. Hệ thống hiển thị thông báo lỗi: "Tên danh mục không vượt quá 100 ký tự" 2. Trường "Tên danh mục" được highlight màu đỏ | F23: 1. Hệ thống hiển thị thông báo lỗi: "Tên danh mục không vượt quá 100 ký tự" 2. Trường "Tên danh mục" được highlight màu đỏ | G23: Passed | H23: 46121 | I23: Hiếu | J23: Passed | K23: 46124 | L23: Hiếu
A24: FUNC-CAT04 | B24: Thêm danh mục - Tên trùng lặp | C24: 1. Admin đăng nhập vào hệ thống 2. Admin truy cập trang quản lý danh mục món ăn 3. Admin nhấn nút "Thêm danh mục mới" 4. Admin nhập tên danh mục đã tồn tại | D24: Admin đã đăng nhập vào hệ thống với quyền quản lý danh mục Tên danh mục tồn tại trong hệ thống | E24: 1. Hệ thống hiển thị thông báo lỗi: Hệ thống hiển thị thông báo lỗi: "Danh mục đã tồn tại. Vui lòng chọn tên khác." 2. Trường "Tên danh mục" được highlight màu đỏ | F24: 1. Hệ thống hiển thị thông báo lỗi: Hệ thống hiển thị thông báo lỗi: "Danh mục đã tồn tại. Vui lòng chọn tên khác." 2. Trường "Tên danh mục" được highlight màu đỏ | G24: Passed | H24: 46121 | I24: Hiếu | J24: Passed | K24: 46124 | L24: Hiếu
A25: FUNC-CAT05 | B25: Thêm danh mục - Upload ảnh hợp lệ | C25: 1. Admin đăng nhập vào hệ thống 2. Admin truy cập trang quản lý danh mục món ăn 3. Admin nhấn nút "Thêm danh mục mới" 4. Admin chọn file ảnh JPG hoặc PNG (< 5MB) | D25: Admin đã đăng nhập vào hệ thống File ảnh có định dạng JPG hoặc PNG, kích thước < 5MB | E25: 1. Ảnh được upload thành công 2. Hiển thị preview ảnh vừa upload | F25: 1. Ảnh được upload thành công 2. Hiển thị preview ảnh vừa upload | G25: Passed | H25: 46121 | I25: Hiếu | J25: Passed | K25: 46124 | L25: Hiếu
A26: FUNC-CAT06 | B26: Thêm danh mục - Upload file sai định dạng | C26: 1. Admin đăng nhập vào hệ thống 2. Admin truy cập trang quản lý danh mục món ăn 3. Admin nhấn nút "Thêm danh mục mới" 4. Admin chọn file .exe hoặc .pdf | D26: Admin đã đăng nhập vào hệ thống | E26: 1. Hệ thống hiển thị thông báo lỗi: "Chỉ chấp nhận file ảnh định dạng JPG, PNG, GIF" 2. File không được upload | F26: 1. Hệ thống hiển thị thông báo lỗi: "Chỉ chấp nhận file ảnh định dạng JPG, PNG, GIF" 2. File không được upload | G26: Passed | H26: 46121 | I26: Hiếu | J26: Passed | K26: 46124 | L26: Hiếu
A27: FUNC-CAT07 | B27: Thêm danh mục - Bỏ trống hình ảnh | C27: 1. Admin đăng nhập vào hệ thống 2. Admin truy cập trang quản lý danh mục món ăn 3. Admin nhấn nút "Thêm danh mục mới" 4. Admin không upload hình ảnh | D27: Admin đã đăng nhập vào hệ thống | E27: 1. Hệ thống hiển thị thông báo lỗi: "Vui lòng điền đầy đủ các trường bắt buộc" 2. Trường "Hình ảnh" được highlight màu đỏ | F27: 1. Hệ thống hiển thị thông báo lỗi: "Vui lòng điền đầy đủ các trường bắt buộc" 2. Trường "Hình ảnh" được highlight màu đỏ | G27: Passed | H27: 46121 | I27: Hiếu | J27: Passed | K27: 46124 | L27: Hiếu
A28: FUNCTION_SHOW - Chức năng Sửa danh mục
A29: FUNC-CAT08 | B29: Sửa tên danh mục hợp lệ | C29: 1. Admin đăng nhập vào hệ thống 2. Admin truy cập trang quản lý danh mục món ăn 3. Admin nhấn nút "Sửa" trên một danh mục 4. Admin đổi tên danh mục | D29: Admin đã đăng nhập vào hệ thống Tên danh mục mới chưa tồn tại | E29: 1. Hệ thống hiển thị thông báo: "Cập nhật danh mục thành công" 2. Tên danh mục được cập nhật thành tên mới | F29: 1. Hệ thống hiển thị thông báo: "Cập nhật danh mục thành công" 2. Tên danh mục được cập nhật thành tên mới | G29: Passed | H29: 46121 | I29: Hiếu | J29: Passed | K29: 46124 | L29: Hiếu
A30: FUNC-CAT09 | B30: Sửa danh mục - Xóa tên (để trống) | C30: 1. Admin đăng nhập vào hệ thống 2. Admin truy cập trang quản lý danh mục món ăn 3. Admin nhấn nút "Sửa" trên một danh mục 4 Admin xóa hết nội dung trường "Tên danh mục" (để trống) | D30: Admin đã đăng nhập vào hệ thống Có ít nhất 1 danh mục trong hệ thống | E30: 1. Hệ thống hiển thị thông báo lỗi: "Vui lòng nhập tên danh mục" 2. Trường "Tên danh mục" được highlight màu đỏ | F30: 1. Hệ thống hiển thị thông báo lỗi: "Vui lòng nhập tên danh mục" 2. Trường "Tên danh mục" được highlight màu đỏ | G30: Passed | H30: 46121 | I30: Hiếu | J30: Passed | K30: 46124 | L30: Hiếu
A31: FUNC-CAT10 | B31: Sửa danh mục - Tên trùng với danh mục khác | C31: 1. Admin đăng nhập vào hệ thống 2. Admin truy cập trang quản lý danh mục món ăn 3. Admin nhấn nút "Sửa" trên một danh mục 4 Admin đổi tên thành một danh mục đã tồn tại | D31: Admin đã đăng nhập vào hệ thống Tên danh mục mới đã tồn tại | E31: 1. Hệ thống hiển thị thông báo lỗi: Hệ thống hiển thị thông báo lỗi: "Danh mục đã tồn tại. Vui lòng chọn tên khác." 2. Trường "Tên danh mục" được highlight màu đỏ | F31: 1. Hệ thống hiển thị thông báo lỗi: Hệ thống hiển thị thông báo lỗi: "Danh mục đã tồn tại. Vui lòng chọn tên khác." 2. Trường "Tên danh mục" được highlight màu đỏ | G31: Passed | H31: 46121 | I31: Hiếu | J31: Passed | K31: 46124 | L31: Hiếu
A32: FUNC-CAT11 | B32: Sửa danh mục - Không thay đổi gì và lưu | C32: 1. Admin đăng nhập vào hệ thống 2. Admin truy cập trang quản lý danh mục món ăn 3. Admin nhấn nút "Sửa" trên một danh mục 4. Admin không thay đổi bất kỳ thông tin nào | D32: Admin đã đăng nhập vào hệ thống Có ít nhất 1 danh mục trong hệ thống | E32: Dữ liệu không thay đổi trong database | F32: Dữ liệu không thay đổi trong database | G32: Passed | H32: 46121 | I32: Hiếu | J32: Passed | K32: 46124 | L32: Hiếu
A33: FUNC-CAT12 | B33: Sửa danh mục - Hủy chỉnh sửa | C33: 1. Admin đăng nhập vào hệ thống 2. Admin truy cập trang quản lý danh mục món ăn 3. Admin nhấn nút "Sửa" trên một danh mục 4. Admin nhấn nút "Hủy" hoặc nút X để đóng form | D33: Admin đã đăng nhập vào hệ thống | E33: 1. Form sửa đóng lại 2. Không có thông báo lỗi hoặc thành công 3. Danh sách danh mục hiển thị như cũ | F33: 1. Form sửa đóng lại 2. Không có thông báo lỗi hoặc thành công 3. Danh sách danh mục hiển thị như cũ | G33: Passed | H33: 46121 | I33: Hiếu | J33: Passed | K33: 46124 | L33: Hiếu
A34: FUNCTION_SHOW - Chức năng Xóa danh mục
A35: FUNC-CAT13 | B35: Xóa danh mục bình thường (Soft Delete) | C35: 1. Admin đăng nhập vào hệ thống 2. Admin truy cập trang quản lý danh mục món ăn 3. Admin nhấn nút "Xóa" trên một danh mục 4. Hệ thống hiển thị dialog xác nhận và Admin nhấn nút "Xác nhận" | D35: Admin đã đăng nhập vào hệ thống Danh mục chưa có món ăn nào | E35: 1. Hệ thống hiển thị thông báo: "Xóa danh mục thành công" 2. Danh mục biến mất khỏi danh sách chính 3. Danh mục được chuyển sang tab "Danh mục đã xóa" | F35: 1. Thông báo "xHệ thống hiển thị thông báo: "Xóa danh mục thành công" 2. Danh mục biến mất khỏi danh sách chính 3. Danh mục được chuyển sang tab "Danh mục đã xóa" | G35: Passed | H35: 46121 | I35: Hiếu | J35: Passed | K35: 46124 | L35: Hiếu
A36: FUNC-CAT14 | B36: Xóa danh mục - Hủy xóa | C36: 1. Admin đăng nhập vào hệ thống 2. Admin truy cập trang quản lý danh mục món ăn 3. Admin nhấn nút "Xóa" trên một danh mục 4. Hệ thống hiển thị dialog xác nhận và Admin nhấn nút "Hủy" | D36: Admin đã đăng nhập vào hệ thống Danh mục chưa có món ăn nào | E36: 1. Dialog xác nhận đóng lại 2. Danh mục vẫn còn trong danh sách 3. Không có thông báo nào hiển thị | F36: 1. Dialog xác nhận đóng lại 2. Danh mục vẫn còn trong danh sách 3. Không có thông báo nào hiển thị | G36: Passed | H36: 46121 | I36: Hiếu | J36: Passed | K36: 46124 | L36: Hiếu
A37: FUNC-CAT15 | B37: Khôi phục danh mục đã xóa | C37: 1. Admin đăng nhập vào hệ thống 2. Admin truy cập trang quản lý danh mục món ăn 3. Admin chuyển sang tab "Danh mục đã xóa" 4. Admin nhấn nút "Khôi phục" trên một danh mục 5. Hệ thống hiển thị dialog xác nhận và Admin nhấn "Xác nhận" | D37: Admin đã đăng nhập vào hệ thống Danh mục đã bị xóa (soft delete) trước đó | E37: 1. Hệ thống hiển thị thông báo: "Khôi phục danh mục thành công" 2. Danh mục biến mất khỏi tab "Danh mục đã xóa" 3. Danh mục xuất hiện lại trong danh sách chính | F37: 1. Hệ thống hiển thị thông báo: "Khôi phục danh mục thành công" 2. Danh mục biến mất khỏi tab "Danh mục đã xóa" 3. Danh mục xuất hiện lại trong danh sách chính | G37: Passed | H37: 46121 | I37: Hiếu | J37: Passed | K37: 46124 | L37: Hiếu
A38: FUNC-CAT16 | B38: Xóa vĩnh viễn danh mục (Hard Delete) | C38: 1. Admin đăng nhập vào hệ thống 2. Admin truy cập trang quản lý danh mục món ăn 3. Admin chuyển sang tab "Danh mục đã xóa" 4. Admin nhấn nút "Xóa vĩnh viễn" trên một danh mục 5. Hệ thống hiển thị dialog cảnh báo và Admin nhấn "Xác nhận" | D38: Admin đã đăng nhập vào hệ thống Danh mục đã bị xóa (soft delete) trước đó | E38: 1. Hệ thống hiển thị thông báo: "Xóa vĩnh viễn danh mục thành công" 2. Danh mục biến mất hoàn toàn khỏi hệ thống | F38: 1. Hệ thống hiển thị thông báo: "Xóa vĩnh viễn danh mục thành công" 2. Danh mục biến mất hoàn toàn khỏi hệ thống | G38: Passed | H38: 46121 | I38: Hiếu | J38: Passed | K38: 46124 | L38: Hiếu
A39: FUNCTION_SHOW - Chức năng Tìm kiếm danh mục
A40: FUNC-CAT17 | B40: Tìm kiếm chính xác tên danh mục | C40: 1. Admin đăng nhập vào hệ thống 2. Admin truy cập trang quản lý danh mục món ăn 3. Admin nhập từ khóa vào ô tìm kiếm | D40: Admin đã đăng nhập vào hệ thống Danh mục tồn tại trong hệ thống Có nhiều danh mục khác trong hệ thống | E40: 1. Hệ thống hiển thị danh sách kết quả liên quan đến danh mục 2. Các danh mục không liên quan bị ẩn đi | F40: 1. Hệ thống hiển thị danh sách kết quả liên quan đến danh mục 2. Các danh mục không liên quan bị ẩn đi | G40: Passed | H40: 46121 | I40: Hiếu | J40: Passed | K40: 46124 | L40: Hiếu
A41: FUNC-CAT18 | B41: Tìm kiếm không có kết quả | C41: 1. Admin đăng nhập vào hệ thống 2. Admin truy cập trang quản lý danh mục món ăn 3.Admin nhập từ khóa "abcxyz123" vào ô tìm kiếm | D41: Admin đã đăng nhập vào hệ thống Không có danh mục nào có tên chứa "abcxyz123" | E41: Hệ thống hiển thị empty state với thông báo: "Không tìm thấy kết quả phù hợp" | F41: Hệ thống hiển thị empty state với thông báo: "Không tìm thấy kết quả phù hợp" | G41: Passed | H41: 46121 | I41: Hiếu | J41: Passed | K41: 46124 | L41: Hiếu
A42: FUNC-CAT19 | B42: Tìm kiếm với khoảng trắng đầu/cuối | C42: 1. Admin đăng nhập vào hệ thống 2. Admin truy cập trang quản lý danh mục món ăn 3.Admin nhập từ khóa (có khoảng trắng đầu và cuối) vào ô tìm kiếm | D42: Admin đã đăng nhập vào hệ thống Danh mục tồn tại trong hệ thống Có nhiều danh mục khác trong hệ thống | E42: 1. Hệ thống tự động trim (loại bỏ) khoảng trắng đầu/cuối 2. Tìm kiếm với từ khóa và hiển thị kết quả đúng | F42: 1. Hệ thống tự động trim (loại bỏ) khoảng trắng đầu/cuối 2. Tìm kiếm với từ khóa và hiển thị kết quả đúng | G42: Passed | H42: 46121 | I42: Hiếu | J42: Passed | K42: 46124 | L42: Hiếu
...

Sheet Quản lý món ăn
A1: Project Name | B1: XÂY DỰNG HỆ THỐNG QUẢN LÝ NHÀ HÀNG THEO MÔ HÌNH TƯƠNG TÁC SỐ ĐA KÊNH
A2: Module Code | B2: Quản lý món ăn
B3: Hoàn thành | C3: Lỗi | D3: Chưa kiểm tra | E3: Bị chặn | F3: Tổng số trường hợp thử nghiệm
A4: Round 1 | B4: =COUNTIF(G21:G105,"Passed") -> 23 | C4: =COUNTIF(G21:G105,"Failed") -> 0 | D4: =COUNTIF(G21:G36,"Untested") -> 0 | E4: =COUNTIF(G21:G36,"Blocked") -> 0 | F4: =SUM(B4:C4) -> 23
A5: Round 2 | B5: =COUNTIF(J21:J105,"Passed") -> 23 | C5: =COUNTIF(J21:J105,"Failed") -> 0 | D5: =COUNTIF(J21:J36,"Untested") -> 0 | E5: =COUNTIF(J21:J36,"Blocked") -> 0 | F5: =SUM(B5:C5) -> 23
A8: Test Case ID | B8: Mô tả | C8: Hành động | D8: Điều kiện tiên quyết | E8: Kết quả mong đợi | F8: Kết quả thực tế | G8: Kết quả | J8: Kết quả | M8: Chú thích
G9: Vòng 1 | J9: Vòng 2
G10: Trạng thái | H10: Ngày kiểm tra | I10: Người kiểm tra | J10: Trạng thái | K10: Ngày kiểm tra | L10: Người kiểm tra
A11: GUI_SHOW - Giao diện trang Quản lý món ăn
A12: GUI-FOOD01 | B12: Hiển thị danh sách món ăn | C12: 1. Admin đăng nhập vào hệ thống 2. Admin truy cập menu "Quản lý món ăn" 3. Hệ thống tải và hiển thị danh sách món ăn | D12: Admin đã đăng nhập vào hệ thống với quyền quản lý món ăn Hệ thống có ít nhất 1 món ăn trong cơ sở dữ liệu | E12: 1. Hiển thị danh sách đầy đủ các món ăn chưa bị xóa 2. Mỗi món ăn hiển thị: tên món, hình ảnh, giá, danh mục, trạng thái, ngày tạo 3. Hiển thị các nút chức năng: "Thêm món ăn", "Sửa", "Xóa" cho mỗi món | F12: 1. Hiển thị danh sách đầy đủ các món ăn chưa bị xóa 2. Mỗi món ăn hiển thị: tên món, hình ảnh, giá, danh mục, trạng thái, ngày tạo 3. Hiển thị các nút chức năng: "Thêm món ăn", "Sửa", "Xóa" cho mỗi món | G12: Passed | H12: 46121 | I12: Hiếu | J12: Passed | K12: 46124 | L12: Hiếu
A13: GUI-FOOD02 | B13: Hiển thị hình ảnh món ăn | C13: 1. Admin truy cập trang quản lý món ăn 2. Quan sát hình ảnh của các món ăn trong danh sách | D13: Admin đã đăng nhập vào hệ thống | E13: 1. Hình ảnh món ăn hiển thị đúng, rõ nét 2. Hình ảnh có kích thước phù hợp, không bị méo hoặc vỡ | F13: 1. Hình ảnh món ăn hiển thị đúng, rõ nét 2. Hình ảnh có kích thước phù hợp, không bị méo hoặc vỡ | G13: Passed | H13: 46121 | I13: Hiếu | J13: Passed | K13: 46124 | L13: Hiếu
A14: GUI-FOOD03 | B14: Hiển thị các nút chức năng | C14: 1. Admin truy cập trang quản lý món ăn 2. Quan sát các nút chức năng trên giao diện | D14: Admin đã đăng nhập vào hệ thống Có ít nhất 1 món ăn trong hệ thống | E14: 1. Hiển thị nút "Thêm món ăn mới" ở vị trí dễ nhìn 2. Mỗi món ăn có nút "Sửa" và "Xóa" với icon rõ ràng | F14: 1. Hiển thị nút "Thêm món ăn mới" ở vị trí dễ nhìn 2. Mỗi món ăn có nút "Sửa" và "Xóa" với icon rõ ràng | G14: Passed | H14: 46121 | I14: Hiếu | J14: Passed | K14: 46124 | L14: Hiếu
A15: GUI-FOOD04 | B15: Hiển thị trạng thái không có dữ liệu | C15: 1. Admin đăng nhập vào hệ thống 2. Admin truy cập trang quản lý món ăn khi chưa có món nào | D15: Admin đã đăng nhập vào hệ thống Hệ thống chưa có món ăn nào (hoặc tất cả đã bị xóa) | E15: Hiển thị thông báo empty state: "Chưa có món ăn nào" | F15: Hiển thị thông báo empty state: "Chưa có món ăn nào" | G15: Passed | H15: 46121 | I15: Hiếu | J15: Passed | K15: 46124 | L15: Hiếu
A16: GUI-FOOD05 | B16: Hiển thị form thêm món ăn | C16: 1. Admin truy cập trang quản lý món ăn 2. Admin nhấn nút "Thêm món ăn mới" 3. Quan sát form thêm món ăn | D16: Admin đã đăng nhập vào hệ thống | E16: 1. Hiển thị modal hoặc form thêm món ăn với các trường 2. Hiển thị nút "Lưu" và "Hủy" 3. Các trường bắt buộc có dấu * màu đỏ | F16: 1. Hiển thị modal hoặc form thêm món ăn với các trường 2. Hiển thị nút "Lưu" và "Hủy" 3. Các trường bắt buộc có dấu * màu đỏ | G16: Passed | H16: 46121 | I16: Hiếu | J16: Passed | K16: 46124 | L16: Hiếu
A17: GUI-FOOD06 | B17: Hiển thị form sửa món ăn | C17: 1. Admin truy cập trang quản lý món ăn 2. Admin nhấn nút "Sửa" trên một món ăn 3. Quan sát form sửa món ăn | D17: Admin đã đăng nhập vào hệ thống Có ít nhất 1 món ăn trong hệ thống | E17: 1. Hiển thị modal hoặc form sửa món ăn 2. Các trường được điền sẵn thông tin hiện tại của món ăn 3. Hiển thị preview hình ảnh hiện tại 4. Hiển thị nút "Lưu thay đổi" và "Hủy" | F17: 1. Hiển thị modal hoặc form sửa món ăn 2. Các trường được điền sẵn thông tin hiện tại của món ăn 3. Hiển thị preview hình ảnh hiện tại 4. Hiển thị nút "Lưu thay đổi" và "Hủy" | G17: Passed | H17: 46121 | I17: Hiếu | J17: Passed | K17: 46124 | L17: Hiếu
A18: GUI-FOOD07 | B18: Hiển thị dialog xác nhận xóa | C18: 1. Admin truy cập trang quản lý món ăn 2. Admin nhấn nút "Xóa" trên một món ăn 3. Quan sát dialog xác nhận | D18: Admin đã đăng nhập vào hệ thống Có ít nhất 1 món ăn trong hệ thống | E18: 1. Hiển thị dialog xác nhận với nội dung: "Bạn có chắc chắn muốn xóa món ăn này không?" 2. Hiển thị tên món ăn sẽ bị xóa 3. Dialog có thể đóng bằng cách nhấn nút Hủy hoặc click ra ngoài | F18: 1. Hiển thị dialog xác nhận với nội dung: "Bạn có chắc chắn muốn xóa món ăn này không?" 2. Hiển thị tên món ăn sẽ bị xóa 3. Dialog có thể đóng bằng cách nhấn nút Hủy hoặc click ra ngoài | G18: Passed | H18: 46121 | I18: Hiếu | J18: Passed | K18: 46124 | L18: Hiếu
A19: GUI-FOOD08 | B19: Hiển thị giá món ăn với định dạng đúng | C19: 1. Admin truy cập trang quản lý món ăn 2. Quan sát cột giá trong danh sách món ăn | D19: Admin đã đăng nhập vào hệ thống Có món ăn với giá đã được nhập | E19: Giá hiển thị đúng định dạng (VD: 50.000 đ hoặc 50,000 VNĐ) | F19: Giá hiển thị đúng định dạng (VD: 50.000 đ hoặc 50,000 VNĐ) | G19: Passed | H19: 46121 | I19: Hiếu | J19: Passed | K19: 46124 | L19: Hiếu
A20: FUNCTION_SHOW - Chức năng Thêm món ăn
A21: FUNC-FOOD01 | B21: Thêm món ăn hợp lệ | C21: 1. Admin đăng nhập vào hệ thống 2. Admin truy cập trang quản lý món ăn 3. Admin nhấn nút "Thêm món ăn mới" 4. Admin nhập đầy đủ các thông tin hợp lệ 5. Admin nhấn nút "Lưu" | D21: Admin đã đăng nhập vào hệ thống với quyền quản lý món ăn Tên món ăn chưa tồn tại trong hệ thống | E21: 1. Hệ thống hiển thị thông báo: "Thêm món ăn thành công" 2. Món ăn mới xuất hiện trong danh sách ở vị trí đầu tiên | F21: 1. Hệ thống hiển thị thông báo: "Thêm món ăn thành công" 2. Món ăn mới xuất hiện trong danh sách ở vị trí đầu tiên | G21: Passed | H21: 46121 | I21: Hiếu | J21: Passed | K21: 46124 | L21: Hiếu
A22: FUNC-FOOD02 | B22: Thêm món ăn - Bỏ trống tên | C22: 1. Admin đăng nhập vào hệ thống 2. Admin truy cập trang quản lý món ăn 3. Admin nhấn nút "Thêm món ăn mới" 4. Admin để trống trường "Tên món ăn" 5. Admin nhấn nút "Lưu" | D22: Admin đã đăng nhập vào hệ thống | E22: 1. Hệ thống hiển thị thông báo lỗi: "Vui lòng điền đầy đủ các trường bắt buộc" 2. Trường "Tên món ăn" được highlight màu đỏ | F22: 1. Hệ thống hiển thị thông báo lỗi: "Vui lòng điền đầy đủ các trường bắt buộc" 2. Trường "Tên món ăn" được highlight màu đỏ | G22: Passed | H22: 46121 | I22: Hiếu | J22: Passed | K22: 46124 | L22: Hiếu
A23: FUNC-FOOD03 | B23: Thêm món ăn - Không chọn danh mục | C23: 1. Admin đăng nhập vào hệ thống 2. Admin truy cập trang quản lý món ăn 3. Admin nhấn nút "Thêm món ăn mới" 4. Admin nhập tên món nhưng không chọn danh mục 5. Admin nhấn nút "Lưu" | D23: Admin đã đăng nhập vào hệ thống | E23: Hệ thống hiển thị thông báo lỗi: "Vui lòng chọn danh mục" | F23: Hệ thống hiển thị thông báo lỗi: "Vui lòng chọn danh mục" | G23: Passed | H23: 46121 | I23: Hiếu | J23: Passed | K23: 46124 | L23: Hiếu
A24: FUNC-FOOD04 | B24: Thêm món ăn - Giá âm | C24: 1. Admin đăng nhập vào hệ thống 2. Admin truy cập trang quản lý món ăn 3. Admin nhấn nút "Thêm món ăn mới" 4. Admin nhập giá âm (VD: -100) 5. Admin nhấn nút "Lưu" | D24: Admin đã đăng nhập vào hệ thống | E24: Hệ thống hiển thị thông báo lỗi: "Giá món ăn phải lớn hơn 0" | F24: Hệ thống hiển thị thông báo lỗi: "Giá món ăn phải lớn hơn 0" | G24: Passed | H24: 46121 | I24: Hiếu | J24: Passed | K24: 46124 | L24: Hiếu
A25: FUNC-FOOD05 | B25: Thêm món ăn - Không upload ảnh | C25: 1. Admin đăng nhập vào hệ thống 2. Admin truy cập trang quản lý món ăn 3. Admin nhấn nút "Thêm món ăn mới" 4. Admin nhập đầy đủ thông tin nhưng không upload ảnh 5. Admin nhấn nút "Lưu" | D25: Admin đã đăng nhập vào hệ thống | E25: Hệ thống hiển thị thông báo lỗi: "Vui lòng chọn hình ảnh" | F25: Hệ thống hiển thị thông báo lỗi: "Vui lòng chọn hình ảnh" | G25: Passed | H25: 46121 | I25: Hiếu | J25: Passed | K25: 46124 | L25: Hiếu
A26: FUNC-FOOD06 | B26: Thêm món ăn - Tên món trùng lặp | C26: 1. Admin đăng nhập vào hệ thống 2. Admin truy cập trang quản lý món ăn 3. Admin nhấn nút "Thêm món ăn mới" 4. Admin nhập tên món đã tồn tại trong hệ thống 5. Admin nhấn nút "Lưu" | D26: Admin đã đăng nhập vào hệ thống Tên món ăn đã tồn tại trong hệ thống | E26: 1. Hệ thống hiển thị thông báo lỗi: "Món ăn đã tồn tại. Vui lòng chọn tên khác." 2. Trường "Tên món ăn" được highlight màu đỏ | F26: 1. Hệ thống hiển thị thông báo lỗi: "Món ăn đã tồn tại. Vui lòng chọn tên khác." 2. Trường "Tên món ăn" được highlight màu đỏ | G26: Passed | H26: 46121 | I26: Hiếu | J26: Passed | K26: 46124 | L26: Hiếu
A27: FUNC-FOOD07 | B27: Thêm món ăn - Upload ảnh hợp lệ | C27: 1. Admin đăng nhập vào hệ thống 2. Admin truy cập trang quản lý món ăn 3. Admin nhấn nút "Thêm món ăn mới" 4. Admin chọn file ảnh JPG hoặc PNG (< 5MB) | D27: Admin đã đăng nhập vào hệ thống File ảnh có định dạng JPG hoặc PNG, kích thước < 5MB | E27: 1. Ảnh được upload thành công 2. Hiển thị preview ảnh vừa upload | F27: 1. Ảnh được upload thành công 2. Hiển thị preview ảnh vừa upload | G27: Passed | H27: 46121 | I27: Hiếu | J27: Passed | K27: 46124 | L27: Hiếu
A28: FUNC-FOOD08 | B28: Thêm món ăn - Upload file sai định dạng | C28: 1. Admin đăng nhập vào hệ thống 2. Admin truy cập trang quản lý món ăn 3. Admin nhấn nút "Thêm món ăn mới" 4. Admin chọn file .exe hoặc .pdf | D28: Admin đã đăng nhập vào hệ thống | E28: 1. Hệ thống hiển thị thông báo lỗi: "Chỉ chấp nhận file ảnh định dạng JPG, PNG, GIF" 2. File không được upload | F28: 1. Hệ thống hiển thị thông báo lỗi: "Chỉ chấp nhận file ảnh định dạng JPG, PNG, GIF" 2. File không được upload | G28: Passed | H28: 46121 | I28: Hiếu | J28: Passed | K28: 46124 | L28: Hiếu
A29: FUNCTION_SHOW - Chức năng Sửa món ăn
A30: FUNC-FOOD09 | B30: Sửa món ăn hợp lệ | C30: 1. Admin đăng nhập vào hệ thống 2. Admin truy cập trang quản lý món ăn 3. Admin nhấn nút "Sửa" trên một món ăn 4. Admin thay đổi thông tin món ăn 5. Admin nhấn nút "Lưu thay đổi" | D30: Admin đã đăng nhập vào hệ thống Có ít nhất 1 món ăn trong hệ thống Tên món ăn mới chưa tồn tại | E30: 1. Hệ thống hiển thị thông báo: "Cập nhật món ăn thành công" 2. Thông tin món ăn được cập nhật trong danh sách | F30: 1. Hệ thống hiển thị thông báo: "Cập nhật món ăn thành công" 2. Thông tin món ăn được cập nhật trong danh sách | G30: Passed | H30: 46121 | I30: Hiếu | J30: Passed | K30: 46124 | L30: Hiếu
A31: FUNC-FOOD10 | B31: Sửa món ăn - Xóa tên (để trống) | C31: 1. Admin đăng nhập vào hệ thống 2. Admin truy cập trang quản lý món ăn 3. Admin nhấn nút "Sửa" trên một món ăn 4. Admin xóa hết nội dung trường "Tên món ăn" 5. Admin nhấn nút "Lưu thay đổi" | D31: Admin đã đăng nhập vào hệ thống Có ít nhất 1 món ăn trong hệ thống | E31: 1. Hệ thống hiển thị thông báo lỗi: "Vui lòng nhập tên món ăn" 2. Trường "Tên món ăn" được highlight màu đỏ | F31: 1. Hệ thống hiển thị thông báo lỗi: "Vui lòng nhập tên món ăn" 2. Trường "Tên món ăn" được highlight màu đỏ | G31: Passed | H31: 46121 | I31: Hiếu | J31: Passed | K31: 46124 | L31: Hiếu
A32: FUNC-FOOD11 | B32: Sửa món ăn - Thay đổi danh mục | C32: 1. Admin đăng nhập vào hệ thống 2. Admin truy cập trang quản lý món ăn 3. Admin nhấn nút "Sửa" trên một món ăn 4. Admin chọn danh mục khác 5. Admin nhấn nút "Lưu thay đổi" | D32: Admin đã đăng nhập vào hệ thống Có ít nhất 1 món ăn trong hệ thống Có ít nhất 2 danh mục trong hệ thống | E32: 1. Hệ thống hiển thị thông báo: "Cập nhật món ăn thành công" 2. Danh mục của món ăn được cập nhật đúng | F32: 1. Hệ thống hiển thị thông báo: "Cập nhật món ăn thành công" 2. Danh mục của món ăn được cập nhật đúng | G32: Passed | H32: 46121 | I32: Hiếu | J32: Passed | K32: 46124 | L32: Hiếu
A33: FUNC-FOOD12 | B33: Sửa món ăn - Thay đổi hình ảnh | C33: 1. Admin đăng nhập vào hệ thống 2. Admin truy cập trang quản lý món ăn 3. Admin nhấn nút "Sửa" trên một món ăn 4. Admin upload ảnh mới 5. Admin nhấn nút "Lưu thay đổi" | D33: Admin đã đăng nhập vào hệ thống Có ít nhất 1 món ăn trong hệ thống | E33: 1. Hệ thống hiển thị thông báo: "Cập nhật món ăn thành công" 2. Hình ảnh món ăn được cập nhật | F33: 1. Hệ thống hiển thị thông báo: "Cập nhật món ăn thành công" 2. Hình ảnh món ăn được cập nhật | G33: Passed | H33: 46121 | I33: Hiếu | J33: Passed | K33: 46124 | L33: Hiếu
A34: FUNC-FOOD13 | B34: Sửa món ăn - Hủy chỉnh sửa | C34: 1. Admin đăng nhập vào hệ thống 2. Admin truy cập trang quản lý món ăn 3. Admin nhấn nút "Sửa" trên một món ăn 4. Admin thay đổi thông tin 5. Admin nhấn nút "Hủy" | D34: Admin đã đăng nhập vào hệ thống Có ít nhất 1 món ăn trong hệ thống | E34: 1. Form sửa đóng lại 2. Dữ liệu không thay đổi 3. Không có thông báo lỗi hoặc thành công | F34: 1. Form sửa đóng lại 2. Dữ liệu không thay đổi 3. Không có thông báo lỗi hoặc thành công | G34: Passed | H34: 46121 | I34: Hiếu | J34: Passed | K34: 46124 | L34: Hiếu
A35: FUNC-FOOD14 | B35: Sửa món ăn - Tên trùng với món khác | C35: 1. Admin đăng nhập vào hệ thống 2. Admin truy cập trang quản lý món ăn 3. Admin nhấn nút "Sửa" trên một món ăn 4. Admin đổi tên thành tên món đã tồn tại 5. Admin nhấn nút "Lưu thay đổi" | D35: Admin đã đăng nhập vào hệ thống Có ít nhất 2 món ăn trong hệ thống | E35: Hệ thống hiển thị thông báo lỗi: "Món ăn đã tồn tại. Vui lòng chọn tên khác." | F35: Hệ thống hiển thị thông báo lỗi: "Món ăn đã tồn tại. Vui lòng chọn tên khác." | G35: Passed | H35: 46121 | I35: Hiếu | J35: Passed | K35: 46124 | L35: Hiếu
A36: FUNC-FOOD15 | B36: Sửa món ăn - Giá âm | C36: 1. Admin đăng nhập vào hệ thống 2. Admin truy cập trang quản lý món ăn 3. Admin nhấn nút "Sửa" trên một món ăn 4. Admin nhập giá âm (VD: -50) 5. Admin nhấn nút "Lưu thay đổi" | D36: Admin đã đăng nhập vào hệ thống Có ít nhất 1 món ăn trong hệ thống | E36: Hệ thống hiển thị thông báo lỗi: "Giá món ăn phải lớn hơn 0" | F36: Hệ thống hiển thị thông báo lỗi: "Giá món ăn phải lớn hơn 0" | G36: Passed | H36: 46121 | I36: Hiếu | J36: Passed | K36: 46124 | L36: Hiếu
A37: FUNCTION_SHOW - Chức năng Xóa món ăn
A38: FUNC-FOOD16 | B38: Xóa món ăn | C38: 1. Admin đăng nhập vào hệ thống 2. Admin truy cập trang quản lý món ăn 3. Admin nhấn nút "Xóa" trên một món ăn 4. Hệ thống hiển thị dialog xác nhận 5. Admin nhấn nút "Xác nhận" | D38: Admin đã đăng nhập vào hệ thống Có ít nhất 1 món ăn trong hệ thống | E38: 1. Hệ thống hiển thị thông báo: "Xóa món ăn thành công" 2. Món ăn biến mất khỏi danh sách chính | F38: 1. Hệ thống hiển thị thông báo: "Xóa món ăn thành công" 2. Món ăn biến mất khỏi danh sách chính | G38: Passed | H38: 46121 | I38: Hiếu | J38: Passed | K38: 46124 | L38: Hiếu
A39: FUNC-FOOD17 | B39: Xóa món ăn - Hủy xóa | C39: 1. Admin đăng nhập vào hệ thống 2. Admin truy cập trang quản lý món ăn 3. Admin nhấn nút "Xóa" trên một món ăn 4. Hệ thống hiển thị dialog xác nhận 5. Admin nhấn nút "Hủy" | D39: Admin đã đăng nhập vào hệ thống Có ít nhất 1 món ăn trong hệ thống | E39: 1. Dialog xác nhận đóng lại 2. Món ăn vẫn còn trong danh sách 3. Không có thông báo nào hiển thị | F39: 1. Dialog xác nhận đóng lại 2. Món ăn vẫn còn trong danh sách 3. Không có thông báo nào hiển thị | G39: Passed | H39: 46121 | I39: Hiếu | J39: Passed | K39: 46124 | L39: Hiếu
A40: FUNC-FOOD18 | B40: Xóa món ăn cuối cùng | C40: 1. Admin đăng nhập vào hệ thống 2. Admin truy cập trang quản lý món ăn 3. Admin xóa hết tất cả món ăn trong danh sách | D40: Admin đã đăng nhập vào hệ thống Có ít nhất 1 món ăn trong hệ thống | E40: 1. Sau khi xóa hết, hiển thị thông báo empty state: "Không có dữ liệu" 2. Hệ thống không bị lỗi | F40: 1. Sau khi xóa hết, hiển thị thông báo empty state: "Không có dữ liệu" 2. Hệ thống không bị lỗi | G40: Passed | H40: 46121 | I40: Hiếu | J40: Passed | K40: 46124 | L40: Hiếu
A41: FUNCTION_SHOW - Chức năng Tìm kiếm món ăn
A42: FUNC-FOOD19 | B42: Tìm kiếm chính xác tên món ăn | C42: 1. Admin đăng nhập vào hệ thống 2. Admin truy cập trang quản lý món ăn 3. Admin nhập từ khóa chính xác vào ô tìm kiếm | D42: Admin đã đăng nhập vào hệ thống Món ăn tồn tại trong hệ thống Có nhiều món ăn khác trong hệ thống | E42: 1. Hệ thống hiển thị danh sách kết quả chứa món ăn đúng 2. Các món ăn không liên quan bị ẩn đi | F42: 1. Hệ thống hiển thị danh sách kết quả chứa món ăn đúng 2. Các món ăn không liên quan bị ẩn đi | G42: Passed | H42: 46121 | I42: Hiếu | J42: Passed | K42: 46124 | L42: Hiếu
...

Sheet Quản lý bàn
A1: Project Name | B1: XÂY DỰNG HỆ THỐNG QUẢN LÝ NHÀ HÀNG THEO MÔ HÌNH TƯƠNG TÁC SỐ ĐA KÊNH
A2: Module Code | B2: Quản lý bàn
B3: Hoàn thành | C3: Lỗi | D3: Chưa kiểm tra | E3: Bị chặn | F3: Tổng số trường hợp thử nghiệm
A4: Round 1 | B4: =COUNTIF(G12:G100,"Passed") -> 39 | C4: =COUNTIF(G12:G100,"Failed") -> 0 | D4: =COUNTIF(G12:G28,"Untested") -> 0 | E4: =COUNTIF(G12:G28,"Blocked") -> 0 | F4: =SUM(B4:C4) -> 39
A5: Round 2 | B5: =COUNTIF(J12:J100,"Passed") -> 39 | C5: =COUNTIF(J12:J100,"Failed") -> 0 | D5: =COUNTIF(J12:J28,"Untested") -> 0 | E5: =COUNTIF(J12:J28,"Blocked") -> 0 | F5: =SUM(B5:C5) -> 39
A8: Test Case ID | B8: Mô tả | C8: Hành động | D8: Điều kiện tiên quyết | E8: Kết quả mong đợi | F8: Kết quả thực tế | G8: Kết quả | J8: Kết quả | M8: Chú thích
G9: Vòng 1 | J9: Vòng 2
G10: Trạng thái | H10: Ngày kiểm tra | I10: Người kiểm tra | J10: Trạng thái | K10: Ngày kiểm tra | L10: Người kiểm tra
A11: GUI_SHOW - Danh sách bàn
A12: GUI-DSB01 | B12: Hiển thị danh sách bàn | C12: 1. Admin đăng nhập vào hệ thống 2. Admin truy cập menu "Quản lý bàn" 3. Hệ thống tải và hiển thị danh sách bàn | D12: Admin đã đăng nhập vào hệ thống với quyền quản lý bàn Hệ thống có ít nhất 1 bàn trong cơ sở dữ liệu | E12: 1. Hiển thị tiêu đề "QUẢN LÝ BÀN" rõ ràng 2. Hiển thị bảng danh sách với các cột: Số bàn, ID, Sức chứa, Trạng thái, Vị trí, Ngày tạo, Thao tác 3. Hiển thị các nút chức năng: "Thêm Bàn Mới", "Sửa", "Xóa", "QR Code" | F12: 1. Hiển thị tiêu đề "QUẢN LÝ BÀN" rõ ràng 2. Hiển thị bảng danh sách với các cột: Số bàn, ID, Sức chứa, Trạng thái, Vị trí, Ngày tạo, Thao tác 3. Hiển thị các nút chức năng: "Thêm Bàn Mới", "Sửa", "Xóa", "QR Code" | G12: Passed | H12: 46121 | I12: Lâm | J12: Passed | K12: 46124 | L12: Lâm
A13: GUI-DSB02 | B13: Hiển thị nút "Thêm Bàn Mới" | C13: 1. Admin truy cập trang quản lý bàn 2. Quan sát nút "Thêm Bàn Mới" | D13: Admin đã đăng nhập vào hệ thống | E13: Button hiển thị text "Thêm Bàn Mới", trạng thái Enable, ở vị trí dễ nhìn | F13: Button hiển thị text "Thêm Bàn Mới", trạng thái Enable, ở vị trí dễ nhìn | G13: Passed | H13: 46121 | I13: Lâm | J13: Passed | K13: 46124 | L13: Lâm
A14: GUI-DSB03 | B14: Hiển thị thanh tìm kiếm | C14: 1. Admin truy cập trang quản lý bàn 2. Quan sát thanh tìm kiếm | D14: Admin đã đăng nhập vào hệ thống | E14: Hiển thị search bar với placeholder: "Tìm kiếm...", trạng thái Enable | F14: Hiển thị search bar với placeholder: "Tìm kiếm...", trạng thái Enable | G14: Passed | H14: 46121 | I14: Lâm | J14: Passed | K14: 46124 | L14: Lâm
A15: GUI-DSB04 | B15: Hiển thị trạng thái bàn | C15: 1. Admin truy cập trang quản lý bàn 2. Quan sát cột trạng thái trong bảng | D15: Admin đã đăng nhập vào hệ thống Có bàn với các trạng thái khác nhau | E15: Hiển thị label trạng thái (Trống / Đang sử dụng / Đã đặt / Đang bảo trì) với màu sắc phù hợp | F15: Hiển thị label trạng thái (Trống / Đang sử dụng / Đã đặt / Đang bảo trì) với màu sắc phù hợp | G15: Passed | H15: 46121 | I15: Lâm | J15: Passed | K15: 46124 | L15: Lâm
A16: GUI-DSB05 | B16: Hiển thị các nút thao tác | C16: 1. Admin truy cập trang quản lý bàn 2. Quan sát cột "Thao tác" trong bảng | D16: Admin đã đăng nhập vào hệ thống Có ít nhất 1 bàn trong hệ thống | E16: 1. Hiển thị nút QR Code với icon rõ ràng 2. Hiển thị nút Sửa với icon bút (Edit) 3. Hiển thị nút Xóa với icon thùng rác 4. Tất cả các nút ở trạng thái Enable | F16: 1. Hiển thị nút QR Code với icon rõ ràng 2. Hiển thị nút Sửa với icon bút (Edit) 3. Hiển thị nút Xóa với icon thùng rác 4. Tất cả các nút ở trạng thái Enable | G16: Passed | H16: 46121 | I16: Lâm | J16: Passed | K16: 46124 | L16: Lâm
A17: GUI-DSB06 | B17: Hiển thị form thêm bàn | C17: 1. Admin truy cập trang quản lý bàn 2. Admin nhấn nút "Thêm Bàn Mới" 3. Quan sát form thêm bàn | D17: Admin đã đăng nhập vào hệ thống | E17: 1. Hiển thị modal/popup thêm bàn với các trường: Số bàn, Sức chứa, Vị trí, Trạng thái, Ghi chú 2. Hiển thị nút "Thêm Bàn" và "Hủy" 3. Các trường bắt buộc có dấu * màu đỏ | F17: 1. Hiển thị modal/popup thêm bàn với các trường: Số bàn, Sức chứa, Vị trí, Trạng thái, Ghi chú 2. Hiển thị nút "Thêm Bàn" và "Hủy" 3. Các trường bắt buộc có dấu * màu đỏ | G17: Passed | H17: 46121 | I17: Lâm | J17: Passed | K17: 46124 | L17: Lâm
