Workbook

Sheet Trường hợp kiểm thử
A1: TEST CASE SYSTEM SPRINT 2
A3: Tên dự án | B3: XÂY DỰNG HỆ THỐNG QUẢN LÝ NHÀ HÀNG THEO MÔ HÌNH TƯƠNG TÁC SỐ ĐA KÊNH
A4: STT | B4: Chức năng | C4: Sheet Name | D4: Số lượng Test | E4: Mô tả
A5: 1 | B5: Thanh toán online (Stripe) | C5: Thanh toán online (Stripe) | D5: ='Thanh toán online (Stripe)'!$F$4 -> 17 | E5: Nam
A6: 2 | B6: Thanh toán hóa đơn (Tại quầy) | C6: Thanh toán hóa đơn (Tại quầy) | D6: ='Thanh toán hóa đơn (Tại quầy)'!$F$4 -> 20 | E6: Nam
A7: 3 | B7: AI Chatbot hỗ trợ (Gemini) | C7: AI Chatbot hỗ trợ (Gemini) | D7: ='AI Chatbot hỗ trợ (Gemini)'!$F$4 -> 17 | E7: Nam
A8: 4 | B8: Chat với nhân viên (Socket.io) | C8: Chat với nhân viên (Socket.io) | D8: ='Chat với nhân viên (Socket.io)'!$F$4 -> 20 | E8: Nam
A9: 5 | B9: Đặt bàn | C9: Đặt bàn | D9: ='Đặt bàn'!$F$4 -> 13 | E9: Lâm
A10: 6 | B10: Quản lý danh sách đặt bàn | C10: Quản lý danh sách đặt bàn | D10: ='Quản lý danh sách đặt bàn'!$F$4 -> 12 | E10: Lâm
A11: 7 | B11: Quên mật khẩu | C11: Quên mật khẩu | D11: ='Quên mật khẩu'!$F$4 -> 9 | E11: Ngọc
A12: 8 | B12: Đổi mật khẩu | C12: Đổi mật khẩu | D12: ='Đổi mật khẩu'!$F$4 -> 11 | E12: Ngọc
A13: 9 | B13: Đăng xuất | C13: Đăng xuất | D13: ='Đăng xuất'!$F$4 -> 4 | E13: Ngọc
A14: 10 | B14: Quản lý tài khoản cá nhân | C14: Quản lý tài khoản cá nhân | D14: ='Quản lý tài khoản cá nhân'!$F$4 -> 14 | E14: Ngọc
A15: 11 | B15: Quản lý tài khoản hệ thống | C15: Quản lý tài khoản hệ thống | D15: ='Quản lý tài khoản hệ thống'!$F$4 -> 15 | E15: Ngọc
A16: 12 | B16: Tìm kiếm món ăn | C16: Tìm kiếm món ăn | D16: ='Tìm kiếm món ăn'!$F$4 -> 7 | E16: Hiếu
A17: 13 | B17: Xem chi tiết món ăn | C17: Xem chi tiết món ăn | D17: ='Xem chi tiết món ăn'!$F$4 -> 9 | E17: Hiếu
A18: 14 | B18: Quản lý mã giảm giá | C18: Quản lý mã giảm giá | D18: ='Quản lý mã giảm giá'!$F$4 -> 28 | E18: Hiếu
A19: 15 | B19: Xem khuyến mãi | C19: Xem khuyến mãi | D19: ='Xem khuyến mãi'!$F$4 -> 13 | E19: Hiếu
A20: 16 | B20: Báo cáo thống kê | C20: Báo cáo thống kê | D20: ='Báo cáo thống kê'!$F$4 -> 43 | E20: Nam
D21: =SUM(D5:D20) -> 252

Sheet Báo cáo kiểm tra
A1: Báo cáo thử nghiệm
A3: Tên dự án | B3: Website bán thời trang | E3: Creator | H3: Phạm Nguyễn Đình huy
E4: Người đánh giá/phê duyệt | H4: Cả nhóm
E5: Ngày triển khai | H5: 44114
A6: Ghi chú | B6: Tính năng đang chờ xử lý :
C7: Hoàn thành | E7: Lỗi | G7: Chưa Kiểm tra | I7: Bị chặn | K7: Số trường hợp thử nghiệm | M7: % Thành công | O7: % Coverage
A9: STT | B9: Tên hiển thị | C9: Vòng 1 | D9: Vòng 2 | E9: Vòng 1 | F9: Vòng 2 | G9: Vòng 1 | H9: Vòng 2 | I9: Vòng 1 | J9: Vòng 2 | K9: Vòng 1 | L9: Vòng 2 | M9: Vòng 1 | N9: Vòng 2 | O9: Vòng 1 | P9: Vòng 2
A10: 1 | B10: Đăng nhập | C10: 15 | D10: 15 | E10: 0 | F10: ='[1]Show Bus Routes List'!C6 -> 0 | G10: ='[1]Show Bus Routes List'!D5 -> 0 | H10: ='[1]Show Bus Routes List'!D6 -> 0 | I10: ='[1]Show Bus Routes List'!E5 -> 0 | J10: ='[1]Show Bus Routes List'!E6 -> 0 | K10: 15 | L10: 15 | M10: =ROUND(C10*100/K10,1) -> 100 | N10: =ROUND(D10*100/L10,1) -> 100 | O10: =ROUND((C10+E10)*100/K10,1) -> 100 | P10: =ROUND((D10+F10)*100/L10,1) -> 100
A11: 2 | B11: Quản lý sản phẩm
A12: 3 | B12: Quản lý danh mục | C12: 12 | D12: 12 | E12: 0 | F12: ='[1]Show Bus Stops List'!C6 -> 0 | G12: ='[1]Show Bus Stops List'!D5 -> 0 | H12: ='[1]Show Bus Stops List'!D6 -> 0 | I12: ='[1]Show Bus Stops List'!E5 -> 0 | J12: ='[1]Show Bus Stops List'!E6 -> 0 | K12: 12 | L12: 12 | M12: =ROUND(C12*100/K12,1) -> 100 | N12: =ROUND(D12*100/L12,1) -> 100 | O12: =ROUND((C12+E12)*100/K12,1) -> 100 | P12: =ROUND((D12+F12)*100/L12,1) -> 100
A13: 4 | B13: Quản lý nhãn hiệu
A14: 5 | B14: Quản lý mã khuyến mãi | C14: 8 | D14: 8 | E14: =#REF! -> #REF! | F14: =#REF! -> #REF! | G14: =#REF! -> #REF! | H14: =#REF! -> #REF! | I14: =#REF! -> #REF! | J14: =#REF! -> #REF! | K14: 4 | L14: 4 | M14: =ROUND(C14*100/K14,1) -> 200 | N14: =ROUND(D14*100/L14,1) -> 200 | O14: =ROUND((C14+E14)*100/K14,1) -> #REF! | P14: =ROUND((D14+F14)*100/L14,1) -> #REF!
A15: 6 | B15: Quản lý hóa đơn
A16: 7 | B16: Quản lý tài khoản người dùng | C16: 15 | D16: 15 | E16: 0 | F16: 0 | G16: 0 | H16: 0 | I16: 0 | J16: 0 | K16: 15 | L16: 15 | M16: =ROUND(C16*100/K16,1) -> 100 | N16: 100 | O16: 100 | P16: 100
A17: 8 | B17: Quản lý bài viết | C17: 20 | D17: 20 | E17: =#REF! -> #REF! | F17: =#REF! -> #REF! | G17: =#REF! -> #REF! | H17: =#REF! -> #REF! | I17: =#REF! -> #REF! | J17: =#REF! -> #REF! | K17: 20 | L17: 20 | M17: =ROUND(C17*100/K17,1) -> 100 | N17: =ROUND(D17*100/L17,1) -> 100 | O17: =ROUND((C17+E17)*100/K17,1) -> #REF! | P17: =ROUND((D17+F17)*100/L17,1) -> #REF!
A18: 9 | B18: Quản lý bình luận | C18: 27 | D18: 27 | E18: =#REF! -> #REF! | F18: 0 | G18: =#REF! -> #REF! | H18: =#REF! -> #REF! | I18: =#REF! -> #REF! | J18: 0 | K18: 27 | L18: 27 | M18: =ROUND(C18*100/K18,1) -> 100 | N18: =ROUND(D18*100/L18,1) -> 100 | O18: =ROUND((C18+E18)*100/K18,1) -> #REF! | P18: =ROUND((D18+F18)*100/L18,1) -> 100
A19: 10 | B19: Tìm kiếm | C19: 17 | D19: 17 | E19: 0 | F19: =#REF! -> #REF! | G19: 0 | H19: 0 | I19: 0 | J19: =#REF! -> #REF! | K19: 17 | L19: 17 | M19: =ROUND(C19*100/K19,1) -> 100 | N19: =ROUND(D19*100/L19,1) -> 100 | O19: =ROUND((C19+E19)*100/K19,1) -> 100 | P19: =ROUND((D19+F19)*100/L19,1) -> #REF!
A20: 11 | B20: Quản lý thống kê | C20: 18 | D20: 18 | E20: =#REF! -> #REF! | F20: 0 | G20: =#REF! -> #REF! | H20: =#REF! -> #REF! | I20: =#REF! -> #REF! | J20: 0 | K20: 18 | L20: 18 | M20: =ROUND(C20*100/K20,1) -> 100 | N20: =ROUND(D20*100/L20,1) -> 100 | O20: =ROUND((C20+E20)*100/K20,1) -> #REF! | P20: =ROUND((D20+F20)*100/L20,1) -> 100
B21: Sub total | C21: =SUM(C10:C20) -> 132 | D21: =SUM(D10:D20) -> 132 | E21: =SUM(E10:E20) -> #REF! | F21: =SUM(F10:F20) -> #REF! | G21: =SUM(G10:G20) -> #REF! | H21: =SUM(H10:H20) -> #REF! | I21: =SUM(I10:I20) -> #REF! | J21: =SUM(J10:J20) -> #REF! | ... P21: =SUM(P10:P20) -> #REF!
C22: Vòng 1 | D22: Vòng2
B23: Kiểm tra phủ sóng | C23: =ROUND((C21+E21)*100/K21,1) -> #REF! | D23: =ROUND((D21+F21)*100/L21,1) -> #REF! | E23: %
B24: Kiểm tra thành công phủ sống | C24: =ROUND(C21*100/K21,1) -> 103.1 | D24: =ROUND(D21*100/L21,1) -> 103.1 | E24: %

Sheet Thanh toán online (Stripe)
A1: Project Name | B1: XÂY DỰNG HỆ THỐNG QUẢN LÝ NHÀ HÀNG THEO MÔ HÌNH TƯƠNG TÁC SỐ ĐA KÊNH
A2: Module Code | B2: Thanh toán online (Stripe)
B3: Hoàn thành | C3: Lỗi | D3: Chưa kiểm tra | E3: Bị chặn | F3: Tổng số trường hợp thử nghiệm
A4: Round 1 | B4: =COUNTIF(G12:G100,"Passed") -> 16 | C4: =COUNTIF(G12:G100,"Failed") -> 1 | D4: =COUNTIF(G12:G18,"Untested") -> 0 | E4: =COUNTIF(G12:G18,"Blocked") -> 0 | F4: =SUM(B4:C4) -> 17
A5: Round 2 | B5: =COUNTIF(J12:J100,"Passed") -> 16 | C5: =COUNTIF(J12:J100,"Failed") -> 1 | D5: =COUNTIF(J12:J18,"Untested") -> 0 | E5: =COUNTIF(J12:J18,"Blocked") -> 0 | F5: =SUM(B5:C5) -> 17
A8: Test Case ID | B8: Mô tả | C8: Hành động | D8: Điều kiện tiên quyết | E8: Kết quả mong đợi | F8: Kết quả thực tế | G8: Kết quả | J8: Kết quả | M8: Chú thích
G9: Vòng 1 | J9: Vòng 2
G10: Trạng thái | H10: Ngày kiểm tra | I10: Người kiểm tra | J10: Trạng thái | K10: Ngày kiểm tra | L10: Người kiểm tra
A11: GUI_SHOW – Trang Quản Lý Đơn Hàng (Trước Khi Thanh Toán)
A12: GUI-TTO01 | B12: [Thanh toán online] Button - chưa đủ điều kiện | C12: 1. Người dùng truy cập trang quản lý đơn hàng khi vẫn còn món chưa được phục vụ | D12: Có ít nhất một món chưa được phục vụ trong đơn | E12: Nút "Thanh toán online (Stripe)" bị vô hiệu hoá, không thể nhấn | F12: Nút "Thanh toán online (Stripe)" bị vô hiệu hoá, không thể nhấn | G12: Passed | H12: 46147 | I12: Nam | J12: Passed | K12: 46148 | L12: Nam
A13: GUI-TTO02 | B13: Thông báo chặn thanh toán khi còn món chưa phục vụ | C13: 1. Người dùng truy cập trang quản lý đơn hàng khi có món đang chờ bếp / đang nấu | D13: Có món đang ở trạng thái chờ bếp hoặc đang nấu | E13: Hiển thị cảnh báo "Chưa thể thanh toán" kèm số lượng món còn chờ | F13: Hiển thị cảnh báo "Chưa thể thanh toán" kèm số lượng món còn chờ | G13: Passed | H13: 46147 | I13: Nam | J13: Passed | K13: 46148 | L13: Nam
A14: GUI-TTO03 | B14: [Thanh toán online] Button - đủ điều kiện | C14: 1. Người dùng truy cập trang quản lý đơn hàng sau khi tất cả món đã được phục vụ | D14: Tất cả món trong đơn đã được phục vụ | E14: Nút "Thanh toán online (Stripe)" được kích hoạt, có thể nhấn | F14: Nút "Thanh toán online (Stripe)" được kích hoạt, có thể nhấn | G14: Passed | H14: 46147 | I14: Nam | J14: Passed | K14: 46148 | L14: Nam
A15: GUI_SHOW – Modal Xem Trước Hóa Đơn (Bill Preview)
A16: GUI-TTO04 | B16: Modal xem trước hóa đơn - hiển thị đúng nội dung | C16: 1. Người dùng nhấn nút "Thanh toán online (Stripe)" | D16: Đã nhấn nút "Thanh toán online", tất cả món đã được phục vụ | E16: Modal hiển thị: số bàn, danh sách món (tên, số lượng, giá), tổng cộng, cảnh báo chuyển hướng sang Stripe | F16: Modal hiển thị: số bàn, danh sách món (tên, số lượng, giá), tổng cộng, cảnh báo chuyển hướng sang Stripe | G16: Passed | H16: 46147 | I16: Nam | J16: Passed | K16: 46148 | L16: Nam
A17: GUI-TTO05 | B17: [Xác nhận thanh toán] Button trong modal | C17: 1. Người dùng nhấn "Thanh toán online" 2. Modal hiển thị | D17: Modal đang hiển thị | E17: Nút hiển thị rõ ràng, trạng thái: enable | F17: Nút hiển thị rõ ràng, trạng thái: enable | G17: Passed | H17: 46147 | I17: Nam | J17: Passed | K17: 46148 | L17: Nam
A18: GUI-TTO06 | B18: [Hủy] Button trong modal | C18: 1. Người dùng nhấn nút "Hủy" trong modal xem trước hóa đơn | D18: Modal đang hiển thị | E18: Nút "Hủy" hiển thị, nhấn vào đóng modal và giữ nguyên đơn hàng | F18: Nút "Hủy" hiển thị, nhấn vào đóng modal và giữ nguyên đơn hàng | G18: Passed | H18: 46147 | I18: Nam | J18: Passed | K18: 46148 | L18: Nam
A19: GUI_SHOW – Trang Kết Quả Thanh Toán
A20: GUI-TTO07 | B20: Màn hình đang xác nhận thanh toán | C20: 1. Người dùng được chuyển hướng về hệ thống sau khi hoàn tất thanh toán trên Stripe | D20: Vừa được chuyển về sau khi hoàn tất trên Stripe | E20: Hiển thị vòng xoay tải và thông báo "Đang xác nhận thanh toán..." | F20: Hiển thị vòng xoay tải và thông báo "Đang xác nhận thanh toán..." | G20: Passed | H20: 46147 | I20: Nam | J20: Passed | K20: 46148 | L20: Nam
A21: GUI-TTO08 | B21: Màn hình thanh toán thành công | C21: 1. Người dùng được chuyển hướng về hệ thống sau khi hoàn tất thanh toán trên Stripe | D21: Stripe đã xác nhận giao dịch thành công | E21: Hiển thị thông báo thành công, số bàn, tổng tiền, danh sách món, mã giao dịch và hai nút: "Quét QR để đặt món tiếp" và "Về trang chủ" | F21: Hiển thị thông báo thành công, số bàn, tổng tiền, danh sách món, mã giao dịch và hai nút: "Quét QR để đặt món tiếp" và "Về trang chủ" | G21: Passed | H21: 46147 | I21: Nam | J21: Passed | K21: 46148 | L21: Nam
A22: GUI-TTO09 | B22: Màn hình thanh toán thất bại | C22: 1. Người dùng được chuyển hướng về hệ thống sau khi thanh toán thất bại hoặc bị huỷ trên Stripe | D22: Giao dịch bị từ chối hoặc có lỗi từ Stripe | E22: Hiển thị thông báo lỗi màu đỏ và nút "Thử lại" | F22: Hiển thị thông báo lỗi màu đỏ và nút "Thử lại" | G22: Passed | H22: 46147 | I22: Nam | J22: Passed | K22: 46148 | L22: Nam
A23: GUI-TTO10 | B23: Màn hình đơn hàng đã thay đổi | C23: 1. Người dùng được chuyển hướng về hệ thống sau khi thanh toán, nhưng dữ liệu đơn hàng đã thay đổi | D23: Đơn hàng bị thay đổi sau khi tạo phiên Stripe | E23: Hiển thị cảnh báo màu vàng "Đơn hàng đã thay đổi. Vui lòng thanh toán lại." và nút quay lại | F23: Hiển thị cảnh báo màu vàng "Đơn hàng đã thay đổi. Vui lòng thanh toán lại." và nút quay lại | G23: Failed | H23: 46147 | I23: Nam | J23: Failed | K23: 46148 | L23: Nam
A24: FUNCTION_SHOW – Luồng Thanh Toán Online
A25: FUNC-TTO01 | B25: Chặn thanh toán khi còn món chưa được phục vụ | C25: 1. Nhấn nút "Thanh toán online (Stripe)" khi còn món chưa phục vụ | D25: Có ít nhất một món ở trạng thái chưa phục vụ | E25: Hệ thống hiển thị thông báo lỗi "Vui lòng chờ tất cả các món được phục vụ trước khi thanh toán", không mở modal | F25: Hệ thống hiển thị thông báo lỗi "Vui lòng chờ tất cả các món được phục vụ trước khi thanh toán", không mở modal | G25: Passed | H25: 46147 | I25: Nam | J25: Passed | K25: 46148 | L25: Nam
A26: FUNC-TTO02 | B26: Mở modal xem trước hóa đơn | C26: 1. Chờ tất cả món được phục vụ 2. Nhấn nút "Thanh toán online (Stripe)" | D26: Tất cả món trong đơn đã được phục vụ | E26: Hệ thống hiển thị modal xem trước hóa đơn với đầy đủ thông tin đơn hàng | F26: Hệ thống hiển thị modal xem trước hóa đơn với đầy đủ thông tin đơn hàng | G26: Passed | H26: 46147 | I26: Nam | J26: Passed | K26: 46148 | L26: Nam
A27: FUNC-TTO03 | B27: Đóng modal bằng nút Hủy | C27: 1. Mở modal xem trước hóa đơn 2. Nhấn nút "Hủy" | D27: Modal đang hiển thị | E27: Modal đóng lại, đơn hàng và trạng thái không thay đổi | F27: Modal đóng lại, đơn hàng và trạng thái không thay đổi | G27: Passed | H27: 46147 | I27: Nam | J27: Passed | K27: 46148 | L27: Nam
A28: FUNC-TTO04 | B28: Xác nhận thanh toán – chuyển sang trang Stripe | C28: 1. Mở modal xem trước hóa đơn 2. Nhấn nút "Xác nhận thanh toán" | D28: Tất cả món đã được phục vụ, modal đang hiển thị | E28: Hệ thống tạo phiên thanh toán Stripe, chuyển hướng trình duyệt sang trang thanh toán của Stripe | F28: Hệ thống tạo phiên thanh toán Stripe, chuyển hướng trình duyệt sang trang thanh toán của Stripe | G28: Passed | H28: 46147 | I28: Nam | J28: Passed | K28: 46148 | L28: Nam
A29: FUNC-TTO05 | B29: Thanh toán thành công trên Stripe | C29: 1. Điền thông tin thẻ hợp lệ trên trang Stripe 2. Xác nhận thanh toán | D29: Đang ở trang thanh toán Stripe với thông tin thẻ hợp lệ | E29: Stripe xử lý thành công → hệ thống chuyển về trang kết quả, hiển thị "Thanh toán thành công. Cảm ơn quý khách!", trạng thái đơn cập nhật thành Paid | F29: Stripe xử lý thành công → hệ thống chuyển về trang kết quả, hiển thị "Thanh toán thành công. Cảm ơn quý khách!", trạng thái đơn cập nhật thành Paid | G29: Passed | H29: 46147 | I29: Nam | J29: Passed | K29: 46148 | L29: Nam
A30: FUNC-TTO06 | B30: Thanh toán thất bại hoặc bị huỷ trên Stripe | C30: 1. Điền thông tin thẻ không hợp lệ hoặc nhấn huỷ trên trang Stripe | D30: Đang ở trang thanh toán Stripe | E30: Hệ thống chuyển về trang lỗi, hiển thị "Thanh toán không thành công. Vui lòng thử lại." và nút "Thử lại" | F30: Hệ thống chuyển về trang lỗi, hiển thị "Thanh toán không thành công. Vui lòng thử lại." và nút "Thử lại" | G30: Passed | H30: 46147 | I30: Nam | J30: Passed | K30: 46148 | L30: Nam
A31: FUNC-TTO07 | B31: Hệ thống polling chờ xác nhận từ Stripe | C31: 1. Hoàn tất thanh toán trên Stripe 2. Chuyển về trang kết quả | D31: Hệ thống chưa nhận được webhook xác nhận từ Stripe | E31: Hệ thống hiển thị "Đang chờ xác nhận từ Stripe...", tự động kiểm tra lại sau mỗi 5 giây (tối đa 60 giây). Sau khi xác nhận thành công → hiển thị trang thành công | F31: Hệ thống hiển thị "Đang chờ xác nhận từ Stripe...", tự động kiểm tra lại sau mỗi 5 giây (tối đa 60 giây). Sau khi xác nhận thành công → hiển thị trang thành công | G31: Passed | H31: 46147 | I31: Nam | J31: Passed | K31: 46148 | L31: Nam

Sheet Thanh toán hóa đơn (Tại quầy)
A1: Project Name | B1: XÂY DỰNG HỆ THỐNG QUẢN LÝ NHÀ HÀNG THEO MÔ HÌNH TƯƠNG TÁC SỐ ĐA KÊNH
A2: Module Code | B2: Thanh toán hóa đơn (Tại quầy)
B3: Hoàn thành | C3: Lỗi | D3: Chưa kiểm tra | E3: Bị chặn | F3: Tổng số trường hợp thử nghiệm
A4: Round 1 | B4: =COUNTIF(G12:G101,"Passed") -> 20 | C4: 0 | D4: =COUNTIF(G12:G21,"Untested") -> 0 | E4: =COUNTIF(G12:G21,"Blocked") -> 0 | F4: =SUM(B4:C4) -> 20
A5: Round 2 | B5: =COUNTIF(J12:J101,"Passed") -> 20 | C5: =COUNTIF(J12:J101,"Failed") -> 0 | D5: =COUNTIF(J12:J21,"Untested") -> 0 | E5: =COUNTIF(J12:J21,"Blocked") -> 0 | F5: =SUM(B5:C5) -> 20
A8: Test Case ID | B8: Mô tả | C8: Hành động | D8: Điều kiện tiên quyết | E8: Kết quả mong đợi | F8: Kết quả thực tế | G8: Kết quả | J8: Kết quả | M8: Chú thích
G9: Vòng 1 | J9: Vòng 2
G10: Trạng thái | H10: Ngày kiểm tra | I10: Người kiểm tra | J10: Trạng thái | K10: Ngày kiểm tra | L10: Người kiểm tra
A11: GUI_SHOW – Trang Cashier Dashboard
A12: GUI-TT01 | B12: Thanh tiêu đề – thông tin Cashier | C12: 1. Nhân viên đăng nhập và truy cập trang Cashier Dashboard | D12: Đăng nhập bằng tài khoản Cashier, vào trang Cashier Dashboard | E12: Hiển thị tiêu đề "Cashier Dashboard", đồng hồ thời gian thực, tên nhân viên đang đăng nhập | F12: Hiển thị tiêu đề "Cashier Dashboard", đồng hồ thời gian thực, tên nhân viên đang đăng nhập | G12: Passed | H12: 46147 | I12: Nam | J12: Passed | K12: 46148 | L12: Nam
A13: GUI-TT02 | B13: Chỉ số thống kê – số đơn chờ thu & tổng tiền | C13: 1. Nhân viên đăng nhập và truy cập trang Cashier Dashboard | D13: Có ít nhất một đơn hàng đang chờ thanh toán tại quầy | E13: Hiển thị số lượng đơn hàng chờ thu và tổng số tiền cần thu trên thanh tiêu đề | F13: Hiển thị số lượng đơn hàng chờ thu và tổng số tiền cần thu trên thanh tiêu đề | G13: Passed | H13: 46147 | I13: Nam | J13: Passed | K13: 46148 | L13: Nam
A14: GUI-TT03 | B14: Trạng thái kết nối realtime | C14: 1. Nhân viên đăng nhập và truy cập trang Cashier Dashboard | D14: Đang ở trang Cashier Dashboard | E14: Hiển thị trạng thái kết nối realtime (xanh: đang kết nối / đỏ: mất kết nối) | F14: Hiển thị trạng thái kết nối realtime (xanh: đang kết nối / đỏ: mất kết nối) | G14: Passed | H14: 46147 | I14: Nam | J14: Passed | K14: 46148 | L14: Nam
A15: GUI-TT04 | B15: Danh sách hóa đơn chờ thanh toán | C15: 1. Nhân viên đăng nhập và truy cập trang Cashier Dashboard | D15: Có ít nhất một đơn hàng chờ thanh toán tại quầy | E15: Hiển thị danh sách đơn hàng bên trái với thông tin: số bàn, số món, tổng tiền, thời gian chờ | F15: Hiển thị danh sách đơn hàng bên trái với thông tin: số bàn, số món, tổng tiền, thời gian chờ | G15: Passed | H15: 46147 | I15: Nam | J15: Passed | K15: 46148 | L15: Nam
A16: GUI-TT05 | B16: Trạng thái không có đơn nào chờ thanh toán | C16: 1. Nhân viên đăng nhập và truy cập trang Cashier Dashboard khi không có đơn chờ | D16: Tất cả đơn hàng đã được thanh toán | E16: Hiển thị thông báo "Không có đơn nào chờ thanh toán" | F16: Hiển thị thông báo "Không có đơn nào chờ thanh toán" | G16: Passed | H16: 46147 | I16: Nam | J16: Passed | K16: 46148 | L16: Nam
A17: GUI-TT06 | B17: Panel chi tiết hóa đơn – khi chưa chọn đơn | C17: 1. Nhân viên truy cập trang Cashier Dashboard và chưa chọn đơn | D17: Không có đơn nào được chọn | E17: Vùng bên phải hiển thị hướng dẫn "Chọn hóa đơn để xem chi tiết" | F17: Vùng bên phải hiển thị hướng dẫn "Chọn hóa đơn để xem chi tiết" | G17: Passed | H17: 46147 | I17: Nam | J17: Passed | K17: 46148 | L17: Nam
A18: GUI-TT07 | B18: Panel chi tiết hóa đơn – khi đã chọn đơn | C18: 1. Nhân viên chọn một hóa đơn từ danh sách bên trái | D18: Đã chọn một đơn hàng từ danh sách | E18: Vùng bên phải hiển thị: số bàn, danh sách món ăn (tên, số lượng, giá), tổng tiền | F18: Vùng bên phải hiển thị: số bàn, danh sách món ăn (tên, số lượng, giá), tổng tiền | G18: Passed | H18: 46147 | I18: Nam | J18: Passed | K18: 46148 | L18: Nam
A19: GUI-TT08 | B19: Ô nhập mã giảm giá | C19: 1. Nhân viên chọn một hóa đơn | D19: Đã chọn một đơn hàng | E19: Hiển thị ô nhập mã giảm giá và nút "Áp dụng", trạng thái: enable | F19: Hiển thị ô nhập mã giảm giá và nút "Áp dụng", trạng thái: enable | G19: Passed | H19: 46147 | I19: Nam | J19: Passed | K19: 46148 | L19: Nam
A20: GUI-TT09 | B20: Công cụ hỗ trợ tính tiền thừa | C20: 1. Nhân viên chọn một hóa đơn | D20: Đã chọn một đơn hàng | E20: Hiển thị ô nhập "Tiền khách đưa" và vùng hiển thị tiền thừa trả lại | F20: Hiển thị ô nhập "Tiền khách đưa" và vùng hiển thị tiền thừa trả lại | G20: Passed | H20: 46147 | I20: Nam | J20: Passed | K20: 46148 | L20: Nam
A21: GUI-TT10 | B21: [In hóa đơn] Button và [Xác nhận đã thu tiền] Button | C21: 1. Nhân viên chọn một hóa đơn | D21: Đã chọn một đơn hàng | E21: Hiển thị đầy đủ hai nút hành động ở cuối panel, trạng thái: enable | F21: Hiển thị đầy đủ hai nút hành động ở cuối panel, trạng thái: enable | G21: Passed | H21: 46147 | I21: Nam | J21: Passed | K21: 46148 | L21: Nam
A22: FUNCTION_SHOW – Chức Năng Thanh Toán Tại Quầy
A23: FUNC-TT01 | B23: Hiển thị danh sách đơn hàng chờ thanh toán | C23: 1. Đăng nhập tài khoản Cashier 2. Truy cập Cashier Dashboard | D23: Có ít nhất một đơn hàng đã hoàn tất và khách yêu cầu thanh toán tại quầy | E23: Hệ thống chỉ hiển thị các đơn hàng đã hoàn tất và có phương thức thanh toán tại quầy | F23: Hệ thống chỉ hiển thị các đơn hàng đã hoàn tất và có phương thức thanh toán tại quầy | G23: Passed | H23: 46147 | I23: Nam | J23: Passed | K23: 46148 | L23: Nam
A24: FUNC-TT02 | B24: Chọn một đơn hàng để xem chi tiết | C24: 1. Nhấn vào một đơn hàng trong danh sách bên trái | D24: Đang ở trang Cashier Dashboard, có đơn hàng trong danh sách | E24: Hệ thống hiển thị chi tiết hóa đơn bên phải: số bàn, danh sách món ăn, tổng tiền. Đơn được chọn có viền nổi bật | F24: Hệ thống hiển thị chi tiết hóa đơn bên phải: số bàn, danh sách món ăn, tổng tiền. Đơn được chọn có viền nổi bật | G24: Passed | H24: 46147 | I24: Nam | J24: Passed | K24: 46148 | L24: Nam
A25: FUNC-TT03 | B25: In hóa đơn kèm mã QR thanh toán | C25: 1. Chọn một đơn hàng 2. Nhấn nút "In hóa đơn" | D25: Đã chọn một đơn hàng trong danh sách | E25: Hệ thống mở cửa sổ in với hóa đơn đầy đủ: tên nhà hàng, số bàn, danh sách món, tổng tiền, mã QR thanh toán (VietQR) | F25: Hệ thống mở cửa sổ in với hóa đơn đầy đủ: tên nhà hàng, số bàn, danh sách món, tổng tiền, mã QR thanh toán (VietQR) | G25: Passed | H25: 46147 | I25: Nam | J25: Passed | K25: 46148 | L25: Nam
A26: FUNC-TT04 | B26: Tính tiền thừa khi nhập tiền khách đưa | C26: 1. Chọn một đơn hàng 2. Nhập số tiền khách đưa vào ô "Tiền khách đưa" 3. Nhập số tiền lớn hơn tổng hóa đơn | D26: Đã chọn đơn hàng | E26: Hệ thống hiển thị số tiền thừa cần trả lại cho khách | F26: Hệ thống hiển thị số tiền thừa cần trả lại cho khách | G26: Passed | H26: 46147 | I26: Nam | J26: Passed | K26: 46148 | L26: Nam
A27: FUNC-TT05 | B27: Không hiển thị tiền thừa khi tiền đưa nhỏ hơn hóa đơn | C27: 1. Chọn một đơn hàng 2. Nhập số tiền khách đưa nhỏ hơn tổng hóa đơn | D27: Đã chọn đơn hàng | E27: Hệ thống không hiển thị phần tính tiền thừa | F27: Hệ thống không hiển thị phần tính tiền thừa | G27: Passed | H27: 46147 | I27: Nam | J27: Passed | K27: 46148 | L27: Nam
A28: FUNC-TT06 | B28: Xác nhận thu tiền thành công – thanh toán tiền mặt | C28: 1. Chọn một đơn hàng 2. Nhấn nút "Xác nhận đã thu tiền" | D28: Đã chọn đơn hàng, khách đã trả tiền mặt | E28: Hệ thống hiển thị thông báo "Thanh toán thành công. Đơn hàng đã được hoàn tất.", đơn hàng biến khỏi danh sách chờ | F28: Hệ thống hiển thị thông báo "Thanh toán thành công. Đơn hàng đã được hoàn tất.", đơn hàng biến khỏi danh sách chờ | G28: Passed | H28: 46147 | I28: Nam | J28: Passed | K28: 46148 | L28: Nam
A29: FUNC-TT07 | B29: Thanh toán qua quét mã QR trên hóa đơn | C29: 1. Chọn một đơn hàng 2. In hóa đơn 3. Khách dùng ứng dụng ngân hàng quét mã QR trên tờ hóa đơn để thanh toán | D29: Hóa đơn đã được in có chứa mã QR hợp lệ | E29: Sau khi khách quét và thanh toán thành công, Cashier nhấn "Xác nhận đã thu tiền". Hệ thống xử lý và xoá đơn khỏi danh sách chờ | F29: Sau khi khách quét và thanh toán thành công, Cashier nhấn "Xác nhận đã thu tiền". Hệ thống xử lý và xoá đơn khỏi danh sách chờ | G29: Passed | H29: 46147 | I29: Nam | J29: Passed | K29: 46148 | L29: Nam
A30: FUNC-TT08 | B30: Nhận thông báo realtime khi có đơn mới yêu cầu thanh toán | C30: 1. Đang ở trang Cashier Dashboard 2. Khách tại bàn nhấn yêu cầu thanh toán tại quầy | D30: Trang đang mở, đang kết nối realtime | E30: Hệ thống tự động hiển thị thông báo "Bàn X yêu cầu thanh toán!" và cập nhật danh sách chờ mà không cần tải lại trang | F30: Hệ thống tự động hiển thị thông báo "Bàn X yêu cầu thanh toán!" và cập nhật danh sách chờ mà không cần tải lại trang | G30: Passed | H30: 46147 | I30: Nam | J30: Passed | K30: 46148 | L30: Nam
A31: FUNC-TT09 | B31: Nhận thông báo realtime khi đơn được thanh toán online | C31: 1. Đang ở trang Cashier Dashboard 2. Khách hoàn tất thanh toán online qua Stripe | D31: Trang đang mở, đang kết nối realtime | E31: Hệ thống hiển thị thông báo "Bàn X vừa thanh toán online thành công!" và tự động cập nhật danh sách | F31: Hệ thống hiển thị thông báo "Bàn X vừa thanh toán online thành công!" và tự động cập nhật danh sách | G31: Passed | H31: 46147 | I31: Nam | J31: Passed | K31: 46148 | L31: Nam
A32: FUNC-TT10 | B32: Làm mới danh sách thủ công | C32: 1. Nhấn nút "Làm mới" trên thanh tiêu đề | D32: Đang ở trang Cashier Dashboard | E32: Hệ thống tải lại danh sách đơn hàng từ máy chủ và cập nhật giao diện | F32: Hệ thống tải lại danh sách đơn hàng từ máy chủ và cập nhật giao diện | G32: Passed | H32: 46147 | I32: Nam | J32: Passed | K32: 46148 | L32: Nam

Sheet AI Chatbot hỗ trợ (Gemini)
A1: Project Name | B1: XÂY DỰNG HỆ THỐNG QUẢN LÝ NHÀ HÀNG THEO MÔ HÌNH TƯƠNG TÁC SỐ ĐA KÊNH
A2: Module Code | B2: AI Chatbot hỗ trợ (Gemini)
B3: Hoàn thành | C3: Lỗi | D3: Chưa kiểm tra | E3: Bị chặn | F3: Tổng số trường hợp thử nghiệm
A4: Round 1 | B4: =COUNTIF(G12:G101,"Passed") -> 16 | C4: =COUNTIF(G12:G101,"Failed") -> 1 | D4: =COUNTIF(G12:G19,"Untested") -> 0 | E4: =COUNTIF(G12:G19,"Blocked") -> 0 | F4: =SUM(B4:C4) -> 17
A5: Round 2 | B5: =COUNTIF(J12:J101,"Passed") -> 17 | C5: =COUNTIF(J12:J101,"Failed") -> 0 | D5: =COUNTIF(J12:J19,"Untested") -> 0 | E5: =COUNTIF(J12:J19,"Blocked") -> 0 | F5: =SUM(B5:C5) -> 17
A8: Test Case ID | B8: Mô tả | C8: Hành động | D8: Điều kiện tiên quyết | E8: Kết quả mong đợi | F8: Kết quả thực tế | G8: Kết quả | J8: Kết quả | M8: Chú thích
G9: Vòng 1 | J9: Vòng 2
G10: Trạng thái | H10: Ngày kiểm tra | I10: Người kiểm tra | J10: Trạng thái | K10: Ngày kiểm tra | L10: Người kiểm tra
A11: GUI_SHOW - Trang Menu Gọi Món
A12: GUI-AI01 | B12: Thanh tiêu đề AI Chatbot | C12: 1. Người dùng mở hộp chat AI | D12: Khách mở hộp chat AI | E12: Tiêu đề hiển thị "Trợ lý AI", dòng phụ "EatEase · Powered by Gemini" và chấm xanh lá trạng thái hoạt động | F12: Tiêu đề hiển thị "Trợ lý AI", dòng phụ "EatEase · Powered by Gemini" và chấm xanh lá trạng thái hoạt động | G12: Passed | H12: 46147 | I12: Nam | J12: Passed | K12: 46148 | L12: Nam
A13: GUI-AI02 | B13: Tin nhắn chào mừng tự động | C13: 1. Người dùng mở hộp chat AI lần đầu | D13: Lần đầu mở hộp chat AI | E13: Hệ thống tự động hiển thị tin nhắn chào từ bot trong cuộc trò chuyện | F13: Hệ thống tự động hiển thị tin nhắn chào từ bot trong cuộc trò chuyện | G13: Passed | H13: 46147 | I13: Nam | J13: Passed | K13: 46148 | L13: Nam
A14: GUI-AI03 | B14: Danh sách câu hỏi gợi ý | C14: 1. Người dùng mở hộp chat AI 2. Chưa gửi bất kỳ câu hỏi nào | D14: Chỉ có tin nhắn chào (chưa gửi câu hỏi nào) | E14: Hiển thị 4 nút gợi ý: "Món đặc biệt của nhà hàng?", "Có món nào cay không?", "Món chay có gì?", "Món nào nhanh nhất?" | F14: Hiển thị 4 nút gợi ý: "Món đặc biệt của nhà hàng?", "Có món nào cay không?", "Món chay có gì?", "Món nào nhanh nhất?" | G14: Passed | H14: 46147 | I14: Nam | J14: Passed | K14: 46148 | L14: Nam
A15: GUI-AI04 | B15: Ẩn câu hỏi gợi ý sau khi đã gửi câu hỏi đầu tiên | C15: 1. Người dùng nhập câu hỏi vào ô chat 2. Nhấn nút Gửi | D15: Sau khi khách gửi ít nhất 1 câu hỏi | E15: Khu vực gợi ý biến mất, chỉ còn khu vực hiển thị lịch sử trò chuyện | F15: Khu vực gợi ý biến mất, chỉ còn khu vực hiển thị lịch sử trò chuyện | G15: Passed | H15: 46147 | I15: Nam | J15: Passed | K15: 46148 | L15: Nam
A16: GUI-AI05 | B16: Ô nhập liệu và nút Gửi | C16: 1. Người dùng mở hộp chat AI | D16: Hộp chat AI đang mở | E16: Hiển thị ô nhập liệu đa dòng với placeholder "Hỏi tôi bất cứ điều gì..." và nút Gửi màu gradient tím | F16: Hiển thị ô nhập liệu đa dòng với placeholder "Hỏi tôi bất cứ điều gì..." và nút Gửi màu gradient tím | G16: Passed | H16: 46147 | I16: Nam | J16: Passed | K16: 46148 | L16: Nam
A17: GUI-AI06 | B17: Chỉ báo AI đang trả lời (Typing indicator) | C17: 1. Người dùng nhập câu hỏi 2. Nhấn nút Gửi 3. Hệ thống bắt đầu xử lý và chờ phản hồi từ AI | D17: AI đang xử lý câu hỏi | E17: Hiển thị biểu tượng bot kèm 3 chấm nhấp nháy trong khu vực chat | F17: Hiển thị biểu tượng bot kèm 3 chấm nhấp nháy trong khu vực chat | G17: Passed | H17: 46147 | I17: Nam | J17: Passed | K17: 46148 | L17: Nam
A18: GUI-AI07 | B18: Nút Gửi trong thời gian cooldown | C18: 1. Người dùng nhập câu hỏi 2. Nhấn nút Gửi 3. Hệ thống kích hoạt cơ chế cooldown | D18: Vừa gửi xong một câu hỏi, hệ thống đang cooldown | E18: Nút Gửi hiển thị đếm ngược giây còn lại (ví dụ: "3", "2", "1") thay vì biểu tượng gửi, và bị vô hiệu hoá | F18: Nút Gửi hiển thị đếm ngược giây còn lại thay vì biểu tượng gửi, và bị vô hiệu hoá | G18: Passed | H18: 46147 | I18: Nam | J18: Passed | K18: 46148 | L18: Nam
A19: GUI-AI08 | B19: Thu nhỏ hộp chat AI (Desktop) | C19: 1. Người dùng nhấn nút mũi tên xuống trên tiêu đề hộp chat | D19: Nhấn nút mũi tên xuống trên tiêu đề | E19: Hộp chat thu gọn thành thanh nhỏ hiển thị "Tiếp tục hội thoại với AI" | F19: Hộp chat thu gọn thành thanh nhỏ hiển thị "Tiếp tục hội thoại với AI" | G19: Passed | H19: 46147 | I19: Nam | J19: Passed | K19: 46148 | L19: Nam
A20: FUNCTION_SHOW – Luồng AI Chatbot
A21: FUNC-AI01 | B21: Chọn câu hỏi gợi ý | C21: 1. Nhấn vào một trong 4 nút gợi ý | D21: Đang ở màn hình chào ban đầu | E21: Câu hỏi được gửi đi ngay, hiển thị bong bóng tin nhắn của khách và AI bắt đầu xử lý | F21: Câu hỏi được gửi đi ngay, hiển thị bong bóng tin nhắn của khách và AI bắt đầu xử lý | G21: Passed | H21: 46147 | I21: Nam | J21: Passed | K21: 46148 | L21: Nam
A22: FUNC-AI02 | B22: Nhập và gửi câu hỏi tự do | C22: 1. Nhập câu hỏi vào ô nhập liệu 2. Nhấn nút Gửi hoặc Enter | D22: Hộp chat đang mở, không trong thời gian cooldown | E22: Câu hỏi xuất hiện trong cuộc trò chuyện, hệ thống gửi đến Gemini AI để xử lý | F22: Câu hỏi xuất hiện trong cuộc trò chuyện, hệ thống gửi đến Gemini AI để xử lý | G22: Passed | H22: 46147 | I22: Nam | J22: Passed | K22: 46148 | L22: Nam
A23: FUNC-AI03 | B23: Gửi bằng phím Enter | C23: 1. Nhập câu hỏi 2. Nhấn Enter | D23: Hộp chat đang mở | E23: Câu hỏi được gửi ngay, tương đương nhấn nút Gửi | F23: Câu hỏi được gửi ngay, tương đương nhấn nút Gửi | G23: Passed | H23: 46147 | I23: Nam | J23: Passed | K23: 46148 | L23: Nam
A24: FUNC-AI04 | B24: Xuống dòng trong ô nhập liệu | C24: 1. Nhập nội dung 2. Nhấn Shift+Enter | D24: Hộp chat đang mở | E24: Ô nhập liệu xuống dòng, không gửi tin nhắn | F24: Ô nhập liệu xuống dòng, không gửi tin nhắn | G24: Passed | H24: 46147 | I24: Nam | J24: Passed | K24: 46148 | L24: Nam
A25: FUNC-AI05 | B25: Nhận phản hồi từ AI thành công | C25: 1. Gửi câu hỏi hợp lệ 2. Chờ AI phản hồi | D25: Kết nối AI hoạt động bình thường | E25: Hệ thống nhận phản hồi từ Gemini và hiển thị câu trả lời trong khu vực chat (bong bóng trái) | F25: Hệ thống nhận phản hồi từ Gemini và hiển thị câu trả lời trong khu vực chat (bong bóng trái) | G25: Failed | H25: 46147 | I25: Nam | J25: Passed | K25: 46148 | L25: Nam
A26: FUNC-AI06 | B26: Chặn gửi khi ô nhập rỗng | C26: 1. Để trống ô nhập liệu 2. Nhấn nút Gửi | D26: Hộp chat đang mở | E26: Hệ thống không gửi, nút Gửi vẫn bị vô hiệu hoá khi ô trống | F26: Hệ thống không gửi, nút Gửi vẫn bị vô hiệu hoá khi ô trống | G26: Passed | H26: 46147 | I26: Nam | J26: Passed | K26: 46148 | L26: Nam
A27: FUNC-AI07 | B27: Chặn gửi trong thời gian AI đang xử lý | C27: 1. Gửi câu hỏi 2. Cố gửi thêm trong khi AI đang trả lời | D27: AI đang trong trạng thái loading | E27: Nút Gửi và ô nhập liệu bị vô hiệu hoá, không thể gửi thêm câu hỏi | F27: Nút Gửi và ô nhập liệu bị vô hiệu hoá, không thể gửi thêm câu hỏi | G27: Passed | H27: 46147 | I27: Nam | J27: Passed | K27: 46148 | L27: Nam
A28: FUNC-AI08 | B28: Xử lý khi AI không phản hồi được | C28: 1. Gửi câu hỏi khi dịch vụ AI gặp sự cố | D28: Dịch vụ Gemini AI không khả dụng | E28: Hệ thống hiển thị thông báo lỗi "Hiện không thể kết nối với chatbot. Vui lòng thử lại sau." | F28: Hệ thống hiển thị thông báo lỗi "Hiện không thể kết nối với chatbot. Vui lòng thử lại sau." | G28: Passed | H28: 46147 | I28: Nam | J28: Passed | K28: 46148 | L28: Nam
A29: FUNC-AI09 | B29: Mở rộng sang trang chat đầy đủ | C29: 1. Nhấn biểu tượng mở rộng trên tiêu đề (Desktop) | D29: Hộp chat AI đang mở | E29: Hệ thống chuyển hướng sang trang chat đầy đủ, lịch sử trò chuyện với AI được giữ nguyên | F29: Hệ thống chuyển hướng sang trang chat đầy đủ, lịch sử trò chuyện với AI được giữ nguyên | G29: Passed | H29: 46147 | I29: Nam | J29: Passed | K29: 46148 | L29: Nam

Sheet Chat với nhân viên (Socket.io)
A1: Project Name | B1: XÂY DỰNG HỆ THỐNG QUẢN LÝ NHÀ HÀNG THEO MÔ HÌNH TƯƠNG TÁC SỐ ĐA KÊNH
A2: Module Code | B2: Chat với nhân viên (Socket.io)
B3: Hoàn thành | C3: Lỗi | D3: Chưa kiểm tra | E3: Bị chặn | F3: Tổng số trường hợp thử nghiệm
A4: Round 1 | B4: =COUNTIF(G12:G101,"Passed") -> 19 | C4: =COUNTIF(G12:G101,"Failed") -> 1 | D4: =COUNTIF(G12:G23,"Untested") -> 0 | E4: =COUNTIF(G12:G23,"Blocked") -> 0 | F4: =SUM(B4:C4) -> 20
A5: Round 2 | B5: =COUNTIF(J12:J101,"Passed") -> 20 | C5: =COUNTIF(J12:J101,"Failed") -> 0 | D5: =COUNTIF(J12:J23,"Untested") -> 0 | E5: =COUNTIF(J12:J23,"Blocked") -> 0 | F5: =SUM(B5:C5) -> 20
A8: Test Case ID | B8: Mô tả | C8: Hành động | D8: Điều kiện tiên quyết | E8: Kết quả mong đợi | F8: Kết quả thực tế | G8: Kết quả | J8: Kết quả | M8: Chú thích
G9: Vòng 1 | J9: Vòng 2
G10: Trạng thái | H10: Ngày kiểm tra | I10: Người kiểm tra | J10: Trạng thái | K10: Ngày kiểm tra | L10: Người kiểm tra
A11: GUI_SHOW – Giao Diện Chat (Phía Customer)
A12: GUI-SC01 | B12: Thanh tiêu đề chat – trạng thái kết nối | C12: 1. Người dùng mở hộp chat hỗ trợ | D12: Khách mở hộp chat hỗ trợ | E12: Tiêu đề hiển thị "Hỗ trợ trực tiếp" và chấm xanh lá kèm chữ "Đang kết nối" | F12: Tiêu đề hiển thị "Hỗ trợ trực tiếp" và chấm xanh lá kèm chữ "Đang kết nối" | G12: Passed | H12: 46147 | I12: Nam | J12: Passed | K12: 46148 | L12: Nam
A13: GUI-SC02 | B13: Chuyển hướng đăng nhập khi chưa xác thực | C13: 1. Khách chưa đăng nhập 2. Nhấn mở hộp chat | D13: Khách chưa đăng nhập (không có session/token hợp lệ) | E13: Hệ thống không cho phép mở hộp chat và chuyển hướng đến trang đăng nhập | F13: Hệ thống không cho phép mở hộp chat và chuyển hướng đến trang đăng nhập | G13: Passed | H13: 46147 | I13: Nam | J13: Passed | K13: 46148 | L13: Nam
A14: GUI-SC03 | B14: Banner chờ nhân viên | C14: 1. Người dùng mở hộp chat hỗ trợ | D14: Yêu cầu kết nối được gửi đi | E14: Hiển thị banner màu vàng "Đang chờ nhân viên phục vụ..." với chấm nhấp nháy | F14: Hiển thị banner màu vàng "Đang chờ nhân viên phục vụ..." với chấm nhấp nháy | G14: Passed | H14: 46147 | I14: Nam | J14: Passed | K14: 46148 | L14: Nam
A15: GUI-SC04 | B15: Banner đã kết nối với nhân viên | C15: 1. Người dùng gửi yêu cầu chat 2. Hệ thống kết nối với nhân viên (Waiter nhận chat) | D15: Waiter đã nhận yêu cầu chat | E15: Hiển thị banner màu xanh lá "[Tên Waiter] đang hỗ trợ bạn" | F15: Hiển thị banner màu xanh lá "[Tên Waiter] đang hỗ trợ bạn" | G15: Passed | H15: 46147 | I15: Nam | J15: Passed | K15: 46148 | L15: Nam
A16: GUI-SC05 | B16: Ô nhập tin nhắn và nút Gửi | C16: 1. Người dùng được kết nối với nhân viên 2. Bắt đầu phiên chat | D16: Đang trong phiên chat với nhân viên | E16: Hiển thị ô nhập liệu đa dòng, placeholder "Nhập tin nhắn..." và nút Gửi màu gradient | F16: Hiển thị ô nhập liệu đa dòng, placeholder "Nhập tin nhắn..." và nút Gửi màu gradient | G16: Passed | H16: 46147 | I16: Nam | J16: Passed | K16: 46148 | L16: Nam
A17: GUI-SC06 | B17: Báo nhân viên đang gõ (Typing indicator) | C17: 1. Nhân viên nhập nội dung tin nhắn 2. Hệ thống phát sự kiện typing qua Socket.io | D17: Waiter đang soạn tin nhắn | E17: Hiển thị biểu tượng tai nghe kèm 3 chấm nhấp nháy trong khu vực chat | F17: Hiển thị biểu tượng tai nghe kèm 3 chấm nhấp nháy trong khu vực chat | G17: Failed | H17: 46147 | I17: Nam | J17: Passed | K17: 46148 | L17: Nam
A18: GUI-SC07 | B18: Trạng thái mất kết nối | C18: 1. Người dùng đang trong phiên chat 2. Kết nối Socket.io bị gián đoạn | D18: Socket.io mất kết nối đột ngột | E18: Tiêu đề chuyển sang "Mất kết nối" màu đỏ, nút Gửi bị vô hiệu hoá | F18: Tiêu đề chuyển sang "Mất kết nối" màu đỏ, nút Gửi bị vô hiệu hoá | G18: Passed | H18: 46147 | I18: Nam | J18: Passed | K18: 46148 | L18: Nam
A19: GUI-SC08 | B19: Màn hình hội thoại đã kết thúc | C19: 1. Nhân viên hoặc hệ thống đóng phiên chat | D19: Waiter hoặc Admin đóng hội thoại | E19: Hiển thị thông báo "Hội thoại đã được đóng. Cảm ơn bạn đã liên hệ!" và nút "Bắt đầu chat mới" | F19: Hiển thị thông báo "Hội thoại đã được đóng. Cảm ơn bạn đã liên hệ!" và nút "Bắt đầu chat mới" | G19: Passed | H19: 46147 | I19: Nam | J19: Passed | K19: 46148 | L19: Nam
A20: GUI-SC09 | B20: Thu nhỏ (minimize) hộp chat | C20: 1. Người dùng nhấn nút thu nhỏ trên tiêu đề hộp chat | D20: Nhấn nút mũi tên xuống trên tiêu đề (Desktop) | E20: Hộp chat thu gọn thành thanh nhỏ hiển thị "Tiếp tục hỗ trợ" | F20: Hộp chat thu gọn thành thanh nhỏ hiển thị "Tiếp tục hỗ trợ" | G20: Passed | H20: 46147 | I20: Nam | J20: Passed | K20: 46148 | L20: Nam
A21: GUI-SC10 | B21: Badge tin nhắn mới khi chat đang thu nhỏ | C21: 1. Người dùng thu nhỏ hộp chat 2. Nhân viên gửi tin nhắn mới | D21: Nhân viên gửi tin khi hộp chat đang thu nhỏ | E21: Xuất hiện chấm đỏ nhấp nháy trên thanh "Tiếp tục hỗ trợ" thông báo có tin mới | F21: Xuất hiện chấm đỏ nhấp nháy trên thanh "Tiếp tục hỗ trợ" thông báo có tin mới | G21: Passed | H21: 46147 | I21: Nam | J21: Passed | K21: 46148 | L21: Nam
A22: GUI_SHOW – Giao Diện Chat (Phía Waiter)
A23: GUI-SC11 | B23: Waiter – Danh sách yêu cầu chat đang chờ | C23: 1. Waiter đăng nhập và vào trang WaiterBoard | D23: Waiter đăng nhập và vào trang WaiterBoard, có ít nhất một yêu cầu chat đang chờ | E23: Hiển thị danh sách thẻ yêu cầu chat với thông tin: tên khách, thời gian chờ và nút "Nhận hỗ trợ" | F23: Hiển thị danh sách thẻ yêu cầu chat với thông tin: tên khách, thời gian chờ và nút "Nhận hỗ trợ" | G23: Passed | H23: 46147 | I23: Nam | J23: Passed | K23: 46148 | L23: Nam
A24: FUNCTION_SHOW – Luồng Chat Support
A25: FUNC-SC01 | B25: Yêu cầu đăng nhập khi mở chat | C25: 1. Người dùng chưa đăng nhập vào hệ thống 2. Nhấn mở hộp chat hỗ trợ | D25: Người dùng chưa đăng nhập (không có session/token hợp lệ) | E25: Hệ thống không cho phép mở hộp chat và chuyển hướng đến trang đăng nhập | F25: Hệ thống không cho phép mở hộp chat và chuyển hướng đến trang đăng nhập | G25: Passed | H25: 46147 | I25: Nam | J25: Passed | K25: 46148 | L25: Nam
A26: FUNC-SC02 | B26: Gửi tin nhắn hợp lệ | C26: 1. Nhập nội dung tin nhắn 2. Nhấn nút Gửi hoặc Enter | D26: Đang trong phiên chat có kết nối | E26: Tin nhắn xuất hiện ngay trong cuộc trò chuyện (bong bóng phải), Waiter nhận được qua realtime | F26: Tin nhắn xuất hiện ngay trong cuộc trò chuyện (bong bóng phải), Waiter nhận được qua realtime | G26: Passed | H26: 46147 | I26: Nam | J26: Passed | K26: 46148 | L26: Nam
A27: FUNC-SC03 | B27: Chặn gửi tin nhắn rỗng | C27: 1. Để trống ô nhập 2. Nhấn nút Gửi | D27: Đang trong phiên chat | E27: Hệ thống không gửi, nút Gửi vẫn bị vô hiệu hoá | F27: Hệ thống không gửi, nút Gửi vẫn bị vô hiệu hoá | G27: Passed | H27: 46147 | I27: Nam | J27: Passed | K27: 46148 | L27: Nam
A28: FUNC-SC04 | B28: Gửi bằng phím Enter | C28: 1. Nhập tin nhắn 2. Nhấn Enter | D28: Đang trong phiên chat | E28: Tin nhắn được gửi ngay như nhấn nút Gửi | F28: Tin nhắn được gửi ngay như nhấn nút Gửi | G28: Passed | H28: 46147 | I28: Nam | J28: Passed | K28: 46148 | L28: Nam
A29: FUNC-SC05 | B29: Nhận tin nhắn từ Waiter theo thời gian thực | C29: 1. Waiter gửi phản hồi cho khách | D29: Đang trong phiên chat đã được assign | E29: Tin nhắn của Waiter hiển thị ngay trong hộp chat của khách (bong bóng trái), không cần tải lại trang | F29: Tin nhắn của Waiter hiển thị ngay trong hộp chat của khách (bong bóng trái), không cần tải lại trang | G29: Passed | H29: 46147 | I29: Nam | J29: Passed | K29: 46148 | L29: Nam
A30: FUNC-SC06 | B30: Waiter nhận và chấp nhận yêu cầu chat | C30: 1. Waiter vào bảng điều khiển 2. Nhấn "Nhận hỗ trợ" trên yêu cầu mới | D30: Có yêu cầu chat đang chờ từ khách | E30: Trạng thái cuộc trò chuyện cập nhật thành "active", banner xanh hiện phía khách | F30: Trạng thái cuộc trò chuyện cập nhật thành "active", banner xanh hiện phía khách | G30: Passed | H30: 46147 | I30: Nam | J30: Passed | K30: 46148 | L30: Nam
A31: FUNC-SC07 | B31: Waiter gửi phản hồi | C31: 1. Waiter nhập phản hồi trong cửa sổ chat 2. Nhấn Gửi | D31: Phiên chat đang active | E31: Phản hồi xuất hiện phía Waiter và đồng bộ ngay lên hộp chat của khách | F31: Phản hồi xuất hiện phía Waiter và đồng bộ ngay lên hộp chat của khách | G31: Passed | H31: 46147 | I31: Nam | J31: Passed | K31: 46148 | L31: Nam
A32: FUNC-SC08 | B32: Bắt đầu chat mới sau khi hội thoại kết thúc | C32: 1. Hội thoại đã bị đóng 2. Nhấn "Bắt đầu chat mới" | D32: Phiên chat đã đóng | E32: Hệ thống tạo yêu cầu mới, quay về trạng thái "chờ nhân viên" | F32: Hệ thống tạo yêu cầu mới, quay về trạng thái "chờ nhân viên" | G32: Passed | H32: 46147 | I32: Nam | J32: Passed | K32: 46148 | L32: Nam
A33: FUNC-SC09 | B33: Mở rộng sang trang chat đầy đủ | C33: 1. Nhấn biểu tượng mở rộng trên tiêu đề (Desktop) | D33: Hộp chat đang mở | E33: Hệ thống chuyển hướng sang trang chat đầy đủ, giữ nguyên lịch sử tin nhắn | F33: Hệ thống chuyển hướng sang trang chat đầy đủ, giữ nguyên lịch sử tin nhắn | G33: Passed | H33: 46147 | I33: Nam | J33: Passed | K33: 46148 | L33: Nam

Sheet Đặt bàn
A1: Project Name | B1: XÂY DỰNG HỆ THỐNG QUẢN LÝ NHÀ HÀNG THEO MÔ HÌNH TƯƠNG TÁC SỐ ĐA KÊNH
A2: Module Code | B2: Đặt bàn
B3: Hoàn thành | C3: Lỗi | D3: Chưa kiểm tra | E3: Bị chặn | F3: Tổng số trường hợp thử nghiệm
A4: Round 1 | B4: =COUNTIF(G12:G90,"Passed") -> 8 | C4: =COUNTIF(G12:G90,"Failed") -> 5 | D4: =COUNTIF(G12:G23,"Untested") -> 0 | E4: =COUNTIF(G12:G23,"Blocked") -> 0 | F4: =SUM(B4:C4) -> 13
A5: Round 2 | B5: =COUNTIF(J12:J90,"Passed") -> 13 | C5: =COUNTIF(J12:J90,"Failed") -> 0 | D5: =COUNTIF(J12:J23,"Untested") -> 0 | E5: =COUNTIF(J12:J23,"Blocked") -> 0 | F5: =SUM(B5:C5) -> 13
A8: Test Case ID | B8: Mô tả | C8: Hành động | D8: Điều kiện tiên quyết | E8: Kết quả mong đợi | F8: Kết quả thực tế | G8: Kết quả | J8: Kết quả | M8: Chú thích
G9: Vòng 1 | J9: Vòng 2
G10: Trạng thái | H10: Ngày kiểm tra | I10: Người kiểm tra | J10: Trạng thái | K10: Ngày kiểm tra | L10: Người kiểm tra
A11: FUNCITON_SHOW - Đặt bàn
A12: FUN-DB01 | B12: Đặt bàn với dữ liệu hợp lệ | C12: Nhập đầy đủ thông tin, nhấn 'Đặt bàn ngay' | D12: Hệ thống hoạt động bình thường | E12: Hiển thị thông báo thành công, lưu DB | F12: Hiển thị thông báo thành công, lưu DB | G12: Passed | H12: 46147 | I12: Lâm | J12: Passed | K12: 46148 | L12: Lâm
A13: FUN-DB02 | B13: Bỏ trống Họ tên | C13: Không nhập họ tên, nhấn đặt bàn | D13: Form đang mở | E13: Hiển thị lỗi 'Họ tên không được để trống' | F13: Hiển thị lỗi 'Họ tên không được để trống' | G13: Passed | H13: 46147 | I13: Lâm | J13: Passed | K13: 46148 | L13: Lâm
A14: FUN-DB03 | B14: Bỏ trống SĐT | C14: Không nhập SĐT, nhấn đặt bàn | D14: Form đang mở | E14: Hiển thị lỗi 'SĐT không được để trống' | F14: Hiển thị lỗi 'SĐT không được để trống' | G14: Passed | H14: 46147 | I14: Lâm | J14: Passed | K14: 46148 | L14: Lâm
A15: FUN-DB04 | B15: SĐT không hợp lệ | C15: Nhập sai định dạng SĐT | D15: Form đang mở | E15: Hiển thị lỗi 'SĐT không hợp lệ' | F15: Nhập sai định dạng vẫn đặt bàn được | G15: Failed | H15: 46147 | I15: Lâm | J15: Passed | K15: 46148 | L15: Lâm
A16: FUN-DB05 | B16: Bỏ trống số người | C16: Không nhập số người | D16: Form đang mở | E16: Không cho chọn bàn | F16: Không cho chọn bàn | G16: Passed | H16: 46147 | I16: Lâm | J16: Passed | K16: 46148 | L16: Lâm
A17: FUN-DB06 | B17: Số người không hợp lệ | C17: Nhập 0 hoặc số âm | D17: Form đang mở | E17: Hiển thị lỗi 'Số người > 0' | F17: Hiển thị lỗi 'Số người > 0' | G17: Failed | H17: 46147 | I17: Lâm | J17: Passed | K17: 46148 | L17: Lâm
A18: FUN-DB07 | B18: Bỏ trống ngày | C18: Không chọn ngày | D18: Form đang mở | E18: Hiển thị lỗi yêu cầu chọn ngày | F18: Không cho chọn bàn | G18: Failed | H18: 46147 | I18: Lâm | J18: Passed | K18: 46148 | L18: Lâm
A19: FUN-DB08 | B19: Ngày quá khứ | C19: Chọn ngày đã qua | D19: Form đang mở | E19: Hiển thị lỗi 'Ngày không hợp lệ' | F19: Không cho chọn ngày quá khứ | G19: Failed | H19: 46147 | I19: Lâm | J19: Passed | K19: 46148 | L19: Lâm
A20: FUN-DB09 | B20: Bỏ trống giờ | C20: Không chọn giờ | D20: Form đang mở | E20: Hiển thị lỗi yêu cầu chọn giờ | F20: Không cho chọn bàn | G20: Failed | H20: 46147 | I20: Lâm | J20: Passed | K20: 46148 | L20: Lâm
A21: FUN-DB10 | B21: Không chọn bàn | C21: Không chọn bàn | D21: Đã nhập các trường khác | E21: Hiển thị lỗi yêu cầu chọn bàn | F21: Hiển thị lỗi yêu cầu chọn bàn | G21: Passed | H21: 46147 | I21: Lâm | J21: Passed | K21: 46148 | L21: Lâm
A22: FUN-DB11 | B22: Load danh sách bàn | C22: Chọn ngày, giờ, số người | D22: Có dữ liệu bàn | E22: Hiển thị bàn phù hợp | F22: Hiển thị bàn phù hợp | G22: Passed | H22: 46147 | I22: Lâm | J22: Passed | K22: 46148 | L22: Lâm
A23: FUN-DB12 | B23: Không có bàn | C23: Chọn thông tin không phù hợp | D23: Không có bàn trống | E23: Hiển thị 'Không có bàn phù hợp' | F23: Hiển thị 'Không có bàn phù hợp' | G23: Passed | H23: 46147 | I23: Lâm | J23: Passed | K23: 46148 | L23: Lâm
A24: FUN-DB13 | B24: Nhập yêu cầu đặc biệt | C24: Nhập ghi chú và đặt bàn | D24: Form hợp lệ | E24: Lưu ghi chú vào DB | F24: Lưu ghi chú vào DB | G24: Passed | H24: 46147 | I24: Lâm | J24: Passed | K24: 46148 | L24: Lâm

Sheet Quản lý danh sách đặt bàn
A1: Project Name | B1: XÂY DỰNG HỆ THỐNG QUẢN LÝ NHÀ HÀNG THEO MÔ HÌNH TƯƠNG TÁC SỐ ĐA KÊNH
A2: Module Code | B2: Quản lý danh sách đặt bàn
B3: Hoàn thành | C3: Lỗi | D3: Chưa kiểm tra | E3: Bị chặn | F3: Tổng số trường hợp thử nghiệm
A4: Round 1 | B4: =COUNTIF(G12:G89,"Passed") -> 12 | C4: =COUNTIF(G12:G89,"Failed") -> 0 | D4: =COUNTIF(G12:G23,"Untested") -> 0 | E4: =COUNTIF(G12:G23,"Blocked") -> 0 | F4: =SUM(B4:C4) -> 12
A5: Round 2 | B5: =COUNTIF(J12:J89,"Passed") -> 12 | C5: =COUNTIF(J12:J89,"Failed") -> 0 | D5: =COUNTIF(J12:J23,"Untested") -> 0 | E5: =COUNTIF(J12:J23,"Blocked") -> 0 | F5: =SUM(B5:C5) -> 12
A8: Test Case ID | B8: Mô tả | C8: Hành động | D8: Điều kiện tiên quyết | E8: Kết quả mong đợi | F8: Kết quả thực tế | G8: Kết quả | J8: Kết quả | M8: Chú thích
G9: Vòng 1 | J9: Vòng 2
G10: Trạng thái | H10: Ngày kiểm tra | I10: Người kiểm tra | J10: Trạng thái | K10: Ngày kiểm tra | L10: Người kiểm tra
A11: FUNCTION_SHOW - Quản lý danh sách đặt bàn
A12: FUN-QLDB01 | B12: Hiển thị danh sách | C12: Mở trang | D12: Admin login | E12: Hiển thị danh sách đặt bàn của khách hàng | F12: Hiển thị danh sách đặt bàn của khách hàng | G12: Passed | H12: 46147 | I12: Lâm | J12: Passed | K12: 46148 | L12: Lâm
A13: FUN-QLDB02 | B13: Load dữ liệu | C13: Reload trang | D13: Có dữ liệu | E13: Hiển thị đúng | F13: Hiển thị đúng | G13: Passed | H13: 46147 | I13: Lâm | J13: Passed | K13: 46148 | L13: Lâm
A14: FUN-QLDB03 | B14: Làm mới | C14: Nhấn nút | D14: Có data | E14: Reload dữ liệu | F14: Reload dữ liệu | G14: Passed | H14: 46147 | I14: Lâm | J14: Passed | K14: 46148 | L14: Lâm
A15: FUN-QLDB04 | B15: Hiển thị trạng thái (Chờ xác nhận, Đã xác nhận, Đã hủy) | C15: Quan sát | D15: Có dữ liệu | E15: Đúng trạng thái | F15: Đúng trạng thái | G15: Passed | H15: 46147 | I15: Lâm | J15: Passed | K15: 46148 | L15: Lâm
A16: FUN-QLDB05 | B16: Tìm theo tên | C16: Nhập tên | D16: Có dữ liệu | E16: Hiển thị đúng | F16: Hiển thị đúng | G16: Passed | H16: 46147 | I16: Lâm | J16: Passed | K16: 46148 | L16: Lâm
A17: FUN-QLDB06 | B17: Không có kết quả | C17: Nhập sai tên | D17: Không có tên đó | E17: Hiển thị rỗng | F17: Hiển thị rỗng | G17: Passed | H17: 46147 | I17: Lâm | J17: Passed | K17: 46148 | L17: Lâm
A18: FUN-QLDB07 | B18: Clear search | C18: Xóa input | D18: Đã search | E18: Hiển thị full list | F18: Hiển thị full list | G18: Passed | H18: 46147 | I18: Lâm | J18: Passed | K18: 46148 | L18: Lâm
A19: FUN-QLDB08 | B19: Xác nhận | C19: Nhấn button dấu ✔ ở cột "Thao tác" | D19: Đang ở trạng thái "Chờ xác nhận" | E19: Chuyển sang trạng thái "Đã xác nhận" | F19: Chuyển sang trạng thái "Đã xác nhận" | G19: Passed | H19: 46147 | I19: Lâm | J19: Passed | K19: 46148 | L19: Lâm
A20: FUN-QLDB09 | B20: Hủy | C20: Nhấn button dấu x ở cột "Thao tác" | D20: Đang ở trạng thái "Chờ xác nhận hoặc Đã xác nhận" | E20: Chuyển trạng thái | F20: Chuyển sang trạng thái "Đã hủy" | G20: Passed | H20: 46147 | I20: Lâm | J20: Passed | K20: 46148 | L20: Lâm
A21: FUN-QLDB10 | B21: Xem chi tiết | C21: Nhấn button dấu mắt ở cột "Thao tác" | D21: Có dữ liệu | E21: Hiển thị chi tiết đặt bàn | F21: Hiển thị chi tiết đặt bàn | G21: Passed | H21: 46147 | I21: Lâm | J21: Passed | K21: 46148 | L21: Lâm
A22: FUN-QLDB11 | B22: Phân trang | C22: Chuyển trang | D22: >10 data | E22: Load đúng | F22: Load đúng | G22: Passed | H22: 46147 | I22: Lâm | J22: Passed | K22: 46148 | L22: Lâm
A23: FUN-QLDB12 | B23: Hiển thị số trang | C23: Quan sát | D23: Có data | E23: Đúng tổng trang | F23: Đúng tổng trang | G23: Passed | H23: 46147 | I23: Lâm | J23: Passed | K23: 46148 | L23: Lâm

Sheet Quên mật khẩu
A1: Project Name | B1: XÂY DỰNG HỆ THỐNG QUẢN LÝ NHÀ HÀNG THEO MÔ HÌNH TƯƠNG TÁC SỐ ĐA KÊNH
A2: Module Code | B2: Quên mật khẩu
B3: Hoàn thành | C3: Lỗi | D3: Chưa kiểm tra | E3: Bị chặn | F3: Tổng số trường hợp thử nghiệm
A4: Round 1 | B4: =COUNTIF(G12:G87,"Passed") -> 9 | C4: =COUNTIF(G12:G87,"Failed") -> 0 | D4: =COUNTIF(G12:G21,"Untested") -> 0 | E4: =COUNTIF(G12:G21,"Blocked") -> 0 | F4: =SUM(B4:C4) -> 9
A5: Round 2 | B5: =COUNTIF(J12:J87,"Passed") -> 9 | C5: =COUNTIF(J12:J87,"Failed") -> 0 | D5: =COUNTIF(J12:J21,"Untested") -> 0 | E5: =COUNTIF(J12:J21,"Blocked") -> 0 | F5: =SUM(B5:C5) -> 9
A8: Test Case ID | B8: Mô tả | C8: Hành động | D8: Điều kiện tiên quyết | E8: Kết quả mong đợi | F8: Kết quả thực tế | G8: Kết quả | J8: Kết quả | M8: Chú thích
G9: Vòng 1 | J9: Vòng 2
G10: Trạng thái | H10: Ngày kiểm tra | I10: Người kiểm tra | J10: Trạng thái | K10: Ngày kiểm tra | L10: Người kiểm tra
A11: GUI_SHOW Quên mật khẩu
A12: GUI-QMK01 | B12: [Label/Tiêu đề] Hàng chữ "Quên Mật Khẩu" | C12: Đứng tại màn hình Quên mật khẩu, quan sát tiêu đề | D12: Truy cập vào hệ thống (/forgot-password) | E12: Hiển thị rõ, font chữ đậm, canh giữa | F12: Hiển thị rõ, font chữ đậm, canh giữa | G12: Passed | H12: 46148 | I12: Ngọc | J12: Passed | K12: 46148 | L12: Ngọc
A13: GUI-QMK02 | B13: [Email] Textbox | C13: Quan sát ô nhập Email | D13: Truy cập vào hệ thống | E13: Text color: Đen (trắng nếu dark mode). Placeholder: "Nhập email của bạn" Status: enable | F13: Text color: Đen (trắng nếu dark mode). Placeholder: "Nhập email của bạn" Status: enable | G13: Passed | H13: 46148 | I13: Ngọc | J13: Passed | K13: 46148 | L13: Ngọc
A14: GUI-QMK03 | B14: [Quay lại đăng nhập] Link | C14: Quan sát link điều hướng Quay lại | D14: Truy cập vào hệ thống | E14: Text color: Nổi bật (màu xanh highlight), có hiệu ứng hover Status: enable | F14: Text color: Nổi bật (màu xanh highlight), có hiệu ứng hover Status: enable | G14: Passed | H14: 46148 | I14: Ngọc | J14: Passed | K14: 46148 | L14: Ngọc
A15: GUI-QMK04 | B15: [Gửi OTP] Button | C15: Quan sát nút hành động chính "Gửi OTP" | D15: Truy cập vào hệ thống | E15: Nút bự hiển thị chữ "Gửi OTP", chữ màu trắng/nền đen. Status: enable | F15: Nút bự hiển thị chữ "Gửi OTP", chữ màu trắng/nền đen. Status: enable | G15: Passed | H15: 46148 | I15: Ngọc | J15: Passed | K15: 46148 | L15: Ngọc
A16: FUNCTION_SHOW Quên mật khẩu
A17: FUNC-QMK01 | B17: Gửi yêu cầu lấy lại MK thành công | C17: 1. Nhập email đang tồn tại trong hệ thống 2. Click button "Gửi OTP" | D17: Email phải có trong CSDL | E17: Hệ thống báo thành công, gửi OTP qua email và chuyển sang trang Xác nhận OTP (/verification-otp) | F17: Hệ thống báo thành công, gửi OTP qua email và chuyển sang trang Xác nhận OTP (/verification-otp) | G17: Passed | H17: 46148 | I17: Ngọc | J17: Passed | K17: 46148 | L17: Ngọc
A18: FUNC-QMK02 | B18: Gửi yêu cầu lấy lại MK thất bại (Sai Email) | C18: 1. Nhập một email hợp lệ nhưng chưa từng đăng ký tài khoản 2. Click "Gửi OTP" | D18: Email chưa có trong DB | E18: Hệ thống chặn và báo lỗi từ backend (VD: Email không tồn tại) | F18: Hệ thống chặn và báo lỗi từ backend (VD: Email không tồn tại) | G18: Passed | H18: 46148 | I18: Ngọc | J18: Passed | K18: 46148 | L18: Ngọc
A19: FUNC-QMK03 | B19: Để ô Email trống | C19: 1. Không nhập bất kỳ ký tự nào vào ô Email 2. Click button "Gửi OTP" | D19: Truy cập vào hệ thống | E19: Hệ thống chặn gọi API, hiện thông báo: "Vui lòng nhập email" | F19: Hệ thống chặn gọi API, hiện thông báo: "Vui lòng nhập email" | G19: Passed | H19: 46148 | I19: Ngọc | J19: Passed | K19: 46148 | L19: Ngọc
A20: FUNC-QMK04 | B20: Email sai định dạng | C20: 1. Nhập email sai chuẩn (VD: testabc, abc@.com) 2. Click "Gửi OTP" | D20: Truy cập vào hệ thống | E20: Hệ thống chặn gọi API, hiện thông báo: "Vui lòng nhập địa chỉ email hợp lệ" | F20: Hệ thống chặn gọi API, hiện thông báo: "Vui lòng nhập địa chỉ email hợp lệ" | G20: Passed | H20: 46148 | I20: Ngọc | J20: Passed | K20: 46148 | L20: Ngọc
A21: FUNC-QMK05 | B21: Click quay lại Đăng nhập | C21: 1. Click vào đường link "Quay lại đăng nhập." | D21: Truy cập vào hệ thống | E21: Form Quên mật khẩu biến mất, chuyển hướng thành công sang màn hình Đăng nhập (/login) | F21: Form Quên mật khẩu biến mất, chuyển hướng thành công sang màn hình Đăng nhập (/login) | G21: Passed | H21: 46148 | I21: Ngọc | J21: Passed | K21: 46148 | L21: Ngọc

Sheet Đổi mật khẩu
A1: Project Name | B1: XÂY DỰNG HỆ THỐNG QUẢN LÝ NHÀ HÀNG THEO MÔ HÌNH TƯƠNG TÁC SỐ ĐA KÊNH
A2: Module Code | B2: Đổi mật khẩu
B3: Hoàn thành | C3: Lỗi | D3: Chưa kiểm tra | E3: Bị chặn | F3: Tổng số trường hợp thử nghiệm
A4: Round 1 | B4: =COUNTIF(G12:G87,"Passed") -> 11 | C4: =COUNTIF(G12:G87,"Failed") -> 0 | D4: =COUNTIF(G12:G21,"Untested") -> 0 | E4: =COUNTIF(G12:G21,"Blocked") -> 0 | F4: =SUM(B4:C4) -> 11
A5: Round 2 | B5: =COUNTIF(J12:J87,"Passed") -> 11 | C5: =COUNTIF(J12:J87,"Failed") -> 0 | D5: =COUNTIF(J12:J21,"Untested") -> 0 | E5: =COUNTIF(J12:J21,"Blocked") -> 0 | F5: =SUM(B5:C5) -> 11
A8: Test Case ID | B8: Mô tả | C8: Hành động | D8: Điều kiện tiên quyết | E8: Kết quả mong đợi | F8: Kết quả thực tế | G8: Kết quả | J8: Kết quả | M8: Chú thích
G9: Vòng 1 | J9: Vòng 2
G10: Trạng thái | H10: Ngày kiểm tra | I10: Người kiểm tra | J10: Trạng thái | K10: Ngày kiểm tra | L10: Người kiểm tra
A11: GUI_SHOW Đổi mật khẩu
A12: GUI-DMK01 | B12: [Label/Tiêu đề] Cửa sổ Xác minh | C12: đề] Cửa sổ Xác minh KH bấm nút "Đổi mật khẩu" ở Profile, quan sát Modal hiện ra | D12: Đăng nhập thành công vào hệ thống | E12: Hiển thị Modal "Xác minh danh tính của bạn" cùng Icon khóa. Trải nghiệm tối màu nền mượt mà. | F12: Hiển thị Modal "Xác minh danh tính của bạn" cùng Icon khóa. Trải nghiệm tối màu nền mượt mà. | G12: Passed | H12: 46148 | I12: Ngọc | J12: Passed | K12: 46148 | L12: Ngọc
A13: GUI-DMK02 | B13: [Mật khẩu hiện tại] Textbox | C13: Quan sát ô nhập mật khẩu cũ | D13: Modal Xác minh đang mở | E13: Placeholder: "Nhập mật khẩu hiện tại" Có icon con mắt (Toggle visibility) | F13: Placeholder: "Nhập mật khẩu hiện tại" Có icon con mắt (Toggle visibility) | G13: Passed | H13: 46148 | I13: Ngọc | J13: Passed | K13: 46148 | L13: Ngọc
A14: GUI-DMK03 | B14: [Mới & Xác nhận] Textboxes | C14: Quan sát form Đổi mật khẩu sau khi qua bước xác minh | D14: Đăng nhập thành công vào hệ thống | E14: Truy cập trang Reset Password (/reset-password) | F14: Truy cập trang Reset Password (/reset-password) | G14: Passed | H14: 46148 | I14: Ngọc | J14: Passed | K14: 46148 | L14: Ngọc
A15: GUI-DMK04 | B15: [Nút hành động] Buttons | C15: Quan sát nút "Hủy" và "Tiếp tục" trong modal | D15: Modal Xác minh đang mở | E15: 2 nút hiển thị đúng trạng thái. Click Hủy -> Đóng Modal. | F15: 2 nút hiển thị đúng trạng thái. Click Hủy -> Đóng Modal. | G15: Passed | H15: 46148 | I15: Ngọc | J15: Passed | K15: 46148 | L15: Ngọc
A16: FUNCTION_SHOW Đổi mật khẩu
A17: FUNC-DMK01 | B17: Xác minh danh tính thành công | C17: 1. Nhập chính xác Mật khẩu hiện tại 2. Click nút "Tiếp tục" | D17: Modal Xác minh đang mở | E17: Hệ thống báo thành công và tự động chuyển hướng người dùng sang Form Đặt MK Mới (/reset-password) | F17: Hệ thống báo thành công và tự động chuyển hướng người dùng sang Form Đặt MK Mới (/reset-password) | G17: Passed | H17: 46148 | I17: Ngọc | J17: Passed | K17: 46148 | L17: Ngọc
A18: FUNC-DMK02 | B18: Xác minh thất bại (Sai MK cũ) | C18: 1. Nhập sai Mật khẩu hiện tại 2. Click "Tiếp tục" | D18: Modal Xác minh đang mở | E18: Hệ thống báo lỗi từ máy chủ (VD: Mật khẩu không đúng) | F18: Hệ thống báo lỗi từ máy chủ (VD: Mật khẩu không đúng) | G18: Passed | H18: 46148 | I18: Ngọc | J18: Passed | K18: 46148 | L18: Ngọc
A19: FUNC-DMK03 | B19: Khóa cảnh báo sai MK 3 lần | C19: 1. Cố tình nhập sai MK liên tục 3 lần 2. Click "Tiếp tục" | D19: Modal Xác minh đang mở | E19: minh đang mở Trả về lỗi: "Bạn đã nhập sai mật khẩu quá 3 lần...". Hệ thống hiển thị thêm link "Bạn quên mật khẩu? Đặt lại mật khẩu" màu xanh dương. | F19: minh đang mở Trả về lỗi: "Bạn đã nhập sai mật khẩu quá 3 lần...". Hệ thống hiển thị thêm link "Bạn quên mật khẩu? Đặt lại mật khẩu" màu xanh dương. | G19: Passed | H19: 46148 | I19: Ngọc | J19: Passed | K19: 46148 | L19: Ngọc
A20: FUNC-DMK04 | B20: Đi tới Quên MK khi bị khóa | C20: 1. Nhập sai 3 lần để hiện link Quên MK 2. Bấm vào chữ "Đặt lại mật khẩu" | D20: Link quên mật khẩu phải đang hiển thị | E20: Modal đóng lại. Hệ thống chuyển hướng ra khỏi Profile và vào trang /forgot-password | F20: Modal đóng lại. Hệ thống chuyển hướng ra khỏi Profile và vào trang /forgot-password | G20: Passed | H20: 46148 | I20: Ngọc | J20: Passed | K20: 46148 | L20: Ngọc
A21: FUNC-DMK05 | B21: Mật khẩu mới không khớp | C21: 1. Nhập MK mới 2. Nhập Xác nhận MK là một chuỗi khác 3. Bấm Đổi MK | D21: Đang ở /reset-password | E21: Hệ thống chặn gọi API, hiển thị thông báo lỗi: "Mật khẩu và mật khẩu xác nhận phải giống nhau" | F21: Hệ thống chặn gọi API, hiển thị thông báo lỗi: "Mật khẩu và mật khẩu xác nhận phải giống nhau" | G21: Passed | H21: 46148 | I21: Ngọc | J21: Passed | K21: 46148 | L21: Ngọc
A22: FUNC-DMK06 | B22: Mật khẩu mới không khớp | C22: 1. Nhập MK mới 2. Nhập Xác nhận MK là một chuỗi khác 3. Bấm Đổi MK | D22: Đang ở /reset-password | E22: Hệ thống chặn gọi API, hiển thị thông báo lỗi: "Mật khẩu và mật khẩu xác nhận phải giống nhau". | F22: Hệ thống chặn gọi API, hiển thị thông báo lỗi: "Mật khẩu và mật khẩu xác nhận phải giống nhau". | G22: Passed | H22: 46148 | I22: Ngọc | J22: Passed | K22: 46148 | L22: Ngọc
A23: FUNC-DMK07 | B23: Bỏ trống MK mới | C23: 1. Để trống 1 trong 2 ô ở màn hình Reset Password 2. Bấm Cập nhật | D23: Đang ở /reset-password | E23: /reset-password Hệ thống chặn tải dữ liệu: "Vui lòng nhập đầy đủ thông tin" | F23: /reset-password Hệ thống chặn tải dữ liệu: "Vui lòng nhập đầy đủ thông tin" | G23: Passed | H23: 46148 | I23: Ngọc | J23: Passed | K23: 46148 | L23: Ngọc

Sheet Đăng xuất
A1: Project Name | B1: XÂY DỰNG HỆ THỐNG QUẢN LÝ NHÀ HÀNG THEO MÔ HÌNH TƯƠNG TÁC SỐ ĐA KÊNH
A2: Module Code | B2: Đăng xuất
B3: Hoàn thành | C3: Lỗi | D3: Chưa kiểm tra | E3: Bị chặn | F3: Tổng số trường hợp thử nghiệm
A4: Round 1 | B4: =COUNTIF(G12:G78,"Passed") -> 4 | C4: =COUNTIF(G12:G78,"Failed") -> 0 | D4: =COUNTIF(G12:G16,"Untested") -> 0 | E4: =COUNTIF(G12:G16,"Blocked") -> 0 | F4: =SUM(B4:C4) -> 4
A5: Round 2 | B5: =COUNTIF(J12:J78,"Passed") -> 4 | C5: =COUNTIF(J12:J78,"Failed") -> 0 | D5: =COUNTIF(J12:J16,"Untested") -> 0 | E5: =COUNTIF(J12:J16,"Blocked") -> 0 | F5: =SUM(B5:C5) -> 4
A8: Test Case ID | B8: Mô tả | C8: Hành động | D8: Điều kiện tiên quyết | E8: Kết quả mong đợi | F8: Kết quả thực tế | G8: Kết quả | J8: Kết quả | M8: Chú thích
G9: Vòng 1 | J9: Vòng 2
G10: Trạng thái | H10: Ngày kiểm tra | I10: Người kiểm tra | J10: Trạng thái | K10: Ngày kiểm tra | L10: Người kiểm tra
A11: GUI_SHOW Đăng xuất
